Traceback (most recent call last):
  File "/storage/emulated/0/botnet/last.py", line 516, in <module>
    bot.polling(none_stop=True)
  File "/data/user/0/ru.iiec.pydroid3/files/aarch64-linux-android/lib/python3.11/site-packages/telebot/__init__.py", line 1195, in polling
    logger.info('Starting your bot with username: [@%s]', self.user.username)
                                                          ^^^^^^^^^
  File "/data/user/0/ru.iiec.pydroid3/files/aarch64-linux-android/lib/python3.11/site-packages/telebot/__init__.py", line 306, in user
    self._user = self.get_me()
                 ^^^^^^^^^^^^^
  File "/data/user/0/ru.iiec.pydroid3/files/aarch64-linux-android/lib/python3.11/site-packages/telebot/__init__.py", line 1382, in get_me
    apihelper.get_me(self.token)
  File "/data/user/0/ru.iiec.pydroid3/files/aarch64-linux-android/lib/python3.11/site-packages/telebot/apihelper.py", line 202, in get_me
    return _make_request(token, method_url)
           ^^^^^^^^^^^^^^^^^^^^^^^^^^^^^^^^
  File "/data/user/0/ru.iiec.pydroid3/files/aarch64-linux-android/lib/python3.11/site-packages/telebot/apihelper.py", line 168, in _make_request
    json_result = _check_result(method_name, result)
                  ^^^^^^^^^^^^^^^^^^^^^^^^^^^^^^^^^^
  File "/data/user/0/ru.iiec.pydroid3/files/aarch64-linux-android/lib/python3.11/site-packages/telebot/apihelper.py", line 195, in _check_result
    raise ApiTelegramException(method_name, result, result_json)
telebot.apihelper.ApiTelegramException: A request to the Telegram API was unsuccessful. Error code: 401. Description: Unauthorized
