11:55:18
Письмо от gera.madara@mail.ru успешно отправлено на Abuse@telegram.org, spam@telegram.org, security@telegram.org, legal@telegram.org, support@telegram.org,sticker@telegram.org, stopCA@telegram.org, recover@telegram.org, DMCA@telegram.org, sms@telegram.org, dmca@telegram.org.
11:55:21
Письмо от gera.madara@mail.ru успешно отправлено на Abuse@telegram.org, spam@telegram.org, security@telegram.org, legal@telegram.org, support@telegram.org,sticker@telegram.org, stopCA@telegram.org, recover@telegram.org, DMCA@telegram.org, sms@telegram.org, dmca@telegram.org.
11:55:23
Письмо от gera.madara@mail.ru успешно отправлено на Abuse@telegram.org, spam@telegram.org, security@telegram.org, legal@telegram.org, support@telegram.org,sticker@telegram.org, stopCA@telegram.org, recover@telegram.org, DMCA@telegram.org, sms@telegram.org, dmca@telegram.org.
11:55:26
Письмо от gera.madara@mail.ru успешно отправлено на Abuse@telegram.org, spam@telegram.org, security@telegram.org, legal@telegram.org, support@telegram.org,sticker@telegram.org, stopCA@telegram.org, recover@telegram.org, DMCA@telegram.org, sms@telegram.org, dmca@telegram.org.
11:55:28
Письмо от gera.madara@mail.ru успешно отправлено на Abuse@telegram.org, spam@telegram.org, security@telegram.org, legal@telegram.org, support@telegram.org,sticker@telegram.org, stopCA@telegram.org, recover@telegram.org, DMCA@telegram.org, sms@telegram.org, dmca@telegram.org.
11:55:30
Письмо от gera.madara@mail.ru успешно отправлено на Abuse@telegram.org, spam@telegram.org, security@telegram.org, legal@telegram.org, support@telegram.org,sticker@telegram.org, stopCA@telegram.org, recover@telegram.org, DMCA@telegram.org, sms@telegram.org, dmca@telegram.org.
11:55:33
Письмо от gera.madara@mail.ru успешно отправлено на Abuse@telegram.org, spam@telegram.org, security@telegram.org, legal@telegram.org, support@telegram.org,sticker@telegram.org, stopCA@telegram.org, recover@telegram.org, DMCA@telegram.org, sms@telegram.org, dmca@telegram.org.
11:55:35
Письмо от gera.madara@mail.ru успешно отправлено на Abuse@telegram.org, spam@telegram.org, security@telegram.org, legal@telegram.org, support@telegram.org,sticker@telegram.org, stopCA@telegram.org, recover@telegram.org, DMCA@telegram.org, sms@telegram.org, dmca@telegram.org.
11:55:37
Письмо от gera.madara@mail.ru успешно отправлено на Abuse@telegram.org, spam@telegram.org, security@telegram.org, legal@telegram.org, support@telegram.org,sticker@telegram.org, stopCA@telegram.org, recover@telegram.org, DMCA@telegram.org, sms@telegram.org, dmca@telegram.org.
11:55:40
Письмо от gera.madara@mail.ru успешно отправлено на Abuse@telegram.org, spam@telegram.org, security@telegram.org, legal@telegram.org, support@telegram.org,sticker@telegram.org, stopCA@telegram.org, recover@telegram.org, DMCA@telegram.org, sms@telegram.org, dmca@telegram.org.
11:55:42
Письмо от gera.madara@mail.ru успешно отправлено на Abuse@telegram.org, spam@telegram.org, security@telegram.org, legal@telegram.org, support@telegram.org,sticker@telegram.org, stopCA@telegram.org, recover@telegram.org, DMCA@telegram.org, sms@telegram.org, dmca@telegram.org.
12:03:37
Письмо от gera.madara@mail.ru успешно отправлено на Abuse@telegram.org, spam@telegram.org, security@telegram.org, legal@telegram.org, support@telegram.org,sticker@telegram.org, stopCA@telegram.org, recover@telegram.org, DMCA@telegram.org, sms@telegram.org, dmca@telegram.org.
12:03:39
Письмо от gera.madara@mail.ru успешно отправлено на Abuse@telegram.org, spam@telegram.org, security@telegram.org, legal@telegram.org, support@telegram.org,sticker@telegram.org, stopCA@telegram.org, recover@telegram.org, DMCA@telegram.org, sms@telegram.org, dmca@telegram.org.
12:03:41
Письмо от gera.madara@mail.ru успешно отправлено на Abuse@telegram.org, spam@telegram.org, security@telegram.org, legal@telegram.org, support@telegram.org,sticker@telegram.org, stopCA@telegram.org, recover@telegram.org, DMCA@telegram.org, sms@telegram.org, dmca@telegram.org.
12:03:44
Письмо от gera.madara@mail.ru успешно отправлено на Abuse@telegram.org, spam@telegram.org, security@telegram.org, legal@telegram.org, support@telegram.org,sticker@telegram.org, stopCA@telegram.org, recover@telegram.org, DMCA@telegram.org, sms@telegram.org, dmca@telegram.org.
12:03:46
Письмо от gera.madara@mail.ru успешно отправлено на Abuse@telegram.org, spam@telegram.org, security@telegram.org, legal@telegram.org, support@telegram.org,sticker@telegram.org, stopCA@telegram.org, recover@telegram.org, DMCA@telegram.org, sms@telegram.org, dmca@telegram.org.
12:03:49
Письмо от gera.madara@mail.ru успешно отправлено на Abuse@telegram.org, spam@telegram.org, security@telegram.org, legal@telegram.org, support@telegram.org,sticker@telegram.org, stopCA@telegram.org, recover@telegram.org, DMCA@telegram.org, sms@telegram.org, dmca@telegram.org.
12:03:51
Письмо от gera.madara@mail.ru успешно отправлено на Abuse@telegram.org, spam@telegram.org, security@telegram.org, legal@telegram.org, support@telegram.org,sticker@telegram.org, stopCA@telegram.org, recover@telegram.org, DMCA@telegram.org, sms@telegram.org, dmca@telegram.org.
12:03:54
Письмо от gera.madara@mail.ru успешно отправлено на Abuse@telegram.org, spam@telegram.org, security@telegram.org, legal@telegram.org, support@telegram.org,sticker@telegram.org, stopCA@telegram.org, recover@telegram.org, DMCA@telegram.org, sms@telegram.org, dmca@telegram.org.
12:03:56
Письмо от gera.madara@mail.ru успешно отправлено на Abuse@telegram.org, spam@telegram.org, security@telegram.org, legal@telegram.org, support@telegram.org,sticker@telegram.org, stopCA@telegram.org, recover@telegram.org, DMCA@telegram.org, sms@telegram.org, dmca@telegram.org.
12:03:58
Письмо от gera.madara@mail.ru успешно отправлено на Abuse@telegram.org, spam@telegram.org, security@telegram.org, legal@telegram.org, support@telegram.org,sticker@telegram.org, stopCA@telegram.org, recover@telegram.org, DMCA@telegram.org, sms@telegram.org, dmca@telegram.org.
12:04:01
Письмо от gera.madara@mail.ru успешно отправлено на Abuse@telegram.org, spam@telegram.org, security@telegram.org, legal@telegram.org, support@telegram.org,sticker@telegram.org, stopCA@telegram.org, recover@telegram.org, DMCA@telegram.org, sms@telegram.org, dmca@telegram.org.
Письмо не отправлено по причине: (451, b'Ratelimit exceeded for mailbox gera.madara@mail.ru. Try again later.')
Письмо не отправлено по причине: (451, b'Ratelimit exceeded for mailbox gera.madara@mail.ru. Try again later.')
Письмо не отправлено по причине: (451, b'Ratelimit exceeded for mailbox gera.madara@mail.ru. Try again later.')
Письмо не отправлено по причине: (451, b'Ratelimit exceeded for mailbox gera.madara@mail.ru. Try again later.')
Письмо не отправлено по причине: (451, b'Ratelimit exceeded for mailbox gera.madara@mail.ru. Try again later.')
Письмо не отправлено по причине: (451, b'Ratelimit exceeded for mailbox gera.madara@mail.ru. Try again later.')
Письмо не отправлено по причине: (451, b'Ratelimit exceeded for mailbox gera.madara@mail.ru. Try again later.')
Письмо не отправлено по причине: (451, b'Ratelimit exceeded for mailbox gera.madara@mail.ru. Try again later.')
Письмо не отправлено по причине: (451, b'Ratelimit exceeded for mailbox gera.madara@mail.ru. Try again later.')
Письмо не отправлено по причине: (451, b'Ratelimit exceeded for mailbox gera.madara@mail.ru. Try again later.')
Письмо не отправлено по причине: (451, b'Ratelimit exceeded for mailbox gera.madara@mail.ru. Try again later.')
Письмо не отправлено по причине: (451, b'Ratelimit exceeded for mailbox gera.madara@mail.ru. Try again later.')
Письмо не отправлено по причине: (451, b'Ratelimit exceeded for mailbox gera.madara@mail.ru. Try again later.')
Письмо не отправлено по причине: (451, b'Ratelimit exceeded for mailbox gera.madara@mail.ru. Try again later.')
Письмо не отправлено по причине: (451, b'Ratelimit exceeded for mailbox gera.madara@mail.ru. Try again later.')
Письмо не отправлено по причине: (451, b'Ratelimit exceeded for mailbox gera.madara@mail.ru. Try again later.')
Письмо не отправлено по причине: (451, b'Ratelimit exceeded for mailbox gera.madara@mail.ru. Try again later.')
Письмо не отправлено по причине: (451, b'Ratelimit exceeded for mailbox gera.madara@mail.ru. Try again later.')
Письмо не отправлено по причине: (451, b'Ratelimit exceeded for mailbox gera.madara@mail.ru. Try again later.')
Письмо не отправлено по причине: (451, b'Ratelimit exceeded for mailbox gera.madara@mail.ru. Try again later.')
Письмо не отправлено по причине: (451, b'Ratelimit exceeded for mailbox gera.madara@mail.ru. Try again later.')
Письмо не отправлено по причине: (451, b'Ratelimit exceeded for mailbox gera.madara@mail.ru. Try again later.')
12:52:12
Письмо от gera.madara@mail.ru успешно отправлено на Abuse@telegram.org, spam@telegram.org, security@telegram.org, legal@telegram.org, support@telegram.org,sticker@telegram.org, stopCA@telegram.org, recover@telegram.org, DMCA@telegram.org, sms@telegram.org, dmca@telegram.org.
12:52:14
Письмо от gera.madara@mail.ru успешно отправлено на Abuse@telegram.org, spam@telegram.org, security@telegram.org, legal@telegram.org, support@telegram.org,sticker@telegram.org, stopCA@telegram.org, recover@telegram.org, DMCA@telegram.org, sms@telegram.org, dmca@telegram.org.
12:52:17
Письмо от gera.madara@mail.ru успешно отправлено на Abuse@telegram.org, spam@telegram.org, security@telegram.org, legal@telegram.org, support@telegram.org,sticker@telegram.org, stopCA@telegram.org, recover@telegram.org, DMCA@telegram.org, sms@telegram.org, dmca@telegram.org.
12:52:20
Письмо от gera.madara@mail.ru успешно отправлено на Abuse@telegram.org, spam@telegram.org, security@telegram.org, legal@telegram.org, support@telegram.org,sticker@telegram.org, stopCA@telegram.org, recover@telegram.org, DMCA@telegram.org, sms@telegram.org, dmca@telegram.org.
12:52:22
Письмо от gera.madara@mail.ru успешно отправлено на Abuse@telegram.org, spam@telegram.org, security@telegram.org, legal@telegram.org, support@telegram.org,sticker@telegram.org, stopCA@telegram.org, recover@telegram.org, DMCA@telegram.org, sms@telegram.org, dmca@telegram.org.
12:52:24
Письмо от gera.madara@mail.ru успешно отправлено на Abuse@telegram.org, spam@telegram.org, security@telegram.org, legal@telegram.org, support@telegram.org,sticker@telegram.org, stopCA@telegram.org, recover@telegram.org, DMCA@telegram.org, sms@telegram.org, dmca@telegram.org.
12:52:27
Письмо от gera.madara@mail.ru успешно отправлено на Abuse@telegram.org, spam@telegram.org, security@telegram.org, legal@telegram.org, support@telegram.org,sticker@telegram.org, stopCA@telegram.org, recover@telegram.org, DMCA@telegram.org, sms@telegram.org, dmca@telegram.org.
12:52:29
Письмо от gera.madara@mail.ru успешно отправлено на Abuse@telegram.org, spam@telegram.org, security@telegram.org, legal@telegram.org, support@telegram.org,sticker@telegram.org, stopCA@telegram.org, recover@telegram.org, DMCA@telegram.org, sms@telegram.org, dmca@telegram.org.
12:52:31
Письмо от gera.madara@mail.ru успешно отправлено на Abuse@telegram.org, spam@telegram.org, security@telegram.org, legal@telegram.org, support@telegram.org,sticker@telegram.org, stopCA@telegram.org, recover@telegram.org, DMCA@telegram.org, sms@telegram.org, dmca@telegram.org.
12:52:34
Письмо от gera.madara@mail.ru успешно отправлено на Abuse@telegram.org, spam@telegram.org, security@telegram.org, legal@telegram.org, support@telegram.org,sticker@telegram.org, stopCA@telegram.org, recover@telegram.org, DMCA@telegram.org, sms@telegram.org, dmca@telegram.org.
12:52:36
Письмо от gera.madara@mail.ru успешно отправлено на Abuse@telegram.org, spam@telegram.org, security@telegram.org, legal@telegram.org, support@telegram.org,sticker@telegram.org, stopCA@telegram.org, recover@telegram.org, DMCA@telegram.org, sms@telegram.org, dmca@telegram.org.
Письмо не отправлено по причине: (451, b'Ratelimit exceeded for mailbox gera.madara@mail.ru. Try again later.')
Письмо не отправлено по причине: (451, b'Ratelimit exceeded for mailbox gera.madara@mail.ru. Try again later.')
Письмо не отправлено по причине: (451, b'Ratelimit exceeded for mailbox gera.madara@mail.ru. Try again later.')
Письмо не отправлено по причине: (451, b'Ratelimit exceeded for mailbox gera.madara@mail.ru. Try again later.')
Письмо не отправлено по причине: (451, b'Ratelimit exceeded for mailbox gera.madara@mail.ru. Try again later.')
Письмо не отправлено по причине: (451, b'Ratelimit exceeded for mailbox gera.madara@mail.ru. Try again later.')
Письмо не отправлено по причине: (451, b'Ratelimit exceeded for mailbox gera.madara@mail.ru. Try again later.')
Письмо не отправлено по причине: (451, b'Ratelimit exceeded for mailbox gera.madara@mail.ru. Try again later.')
Письмо не отправлено по причине: (451, b'Ratelimit exceeded for mailbox gera.madara@mail.ru. Try again later.')
Письмо не отправлено по причине: (451, b'Ratelimit exceeded for mailbox gera.madara@mail.ru. Try again later.')
Письмо не отправлено по причине: (451, b'Ratelimit exceeded for mailbox gera.madara@mail.ru. Try again later.')
13:29:26
Письмо от gera.madara@mail.ru успешно отправлено на Abuse@telegram.org, spam@telegram.org, security@telegram.org, legal@telegram.org, support@telegram.org,sticker@telegram.org, stopCA@telegram.org, recover@telegram.org, DMCA@telegram.org, sms@telegram.org, dmca@telegram.org.
13:29:30
Письмо от gera.madara@mail.ru успешно отправлено на Abuse@telegram.org, spam@telegram.org, security@telegram.org, legal@telegram.org, support@telegram.org,sticker@telegram.org, stopCA@telegram.org, recover@telegram.org, DMCA@telegram.org, sms@telegram.org, dmca@telegram.org.
13:29:33
Письмо от gera.madara@mail.ru успешно отправлено на Abuse@telegram.org, spam@telegram.org, security@telegram.org, legal@telegram.org, support@telegram.org,sticker@telegram.org, stopCA@telegram.org, recover@telegram.org, DMCA@telegram.org, sms@telegram.org, dmca@telegram.org.
13:29:35
Письмо от gera.madara@mail.ru успешно отправлено на Abuse@telegram.org, spam@telegram.org, security@telegram.org, legal@telegram.org, support@telegram.org,sticker@telegram.org, stopCA@telegram.org, recover@telegram.org, DMCA@telegram.org, sms@telegram.org, dmca@telegram.org.
13:29:38
Письмо от gera.madara@mail.ru успешно отправлено на Abuse@telegram.org, spam@telegram.org, security@telegram.org, legal@telegram.org, support@telegram.org,sticker@telegram.org, stopCA@telegram.org, recover@telegram.org, DMCA@telegram.org, sms@telegram.org, dmca@telegram.org.
13:29:40
Письмо от gera.madara@mail.ru успешно отправлено на Abuse@telegram.org, spam@telegram.org, security@telegram.org, legal@telegram.org, support@telegram.org,sticker@telegram.org, stopCA@telegram.org, recover@telegram.org, DMCA@telegram.org, sms@telegram.org, dmca@telegram.org.
13:29:40
Письмо от gera.madara@mail.ru успешно отправлено на Abuse@telegram.org, spam@telegram.org, security@telegram.org, legal@telegram.org, support@telegram.org,sticker@telegram.org, stopCA@telegram.org, recover@telegram.org, DMCA@telegram.org, sms@telegram.org, dmca@telegram.org.
13:29:42
Письмо от gera.madara@mail.ru успешно отправлено на Abuse@telegram.org, spam@telegram.org, security@telegram.org, legal@telegram.org, support@telegram.org,sticker@telegram.org, stopCA@telegram.org, recover@telegram.org, DMCA@telegram.org, sms@telegram.org, dmca@telegram.org.
13:29:42
Письмо от gera.madara@mail.ru успешно отправлено на Abuse@telegram.org, spam@telegram.org, security@telegram.org, legal@telegram.org, support@telegram.org,sticker@telegram.org, stopCA@telegram.org, recover@telegram.org, DMCA@telegram.org, sms@telegram.org, dmca@telegram.org.
13:29:45
Письмо от gera.madara@mail.ru успешно отправлено на Abuse@telegram.org, spam@telegram.org, security@telegram.org, legal@telegram.org, support@telegram.org,sticker@telegram.org, stopCA@telegram.org, recover@telegram.org, DMCA@telegram.org, sms@telegram.org, dmca@telegram.org.
13:29:45
Письмо от gera.madara@mail.ru успешно отправлено на Abuse@telegram.org, spam@telegram.org, security@telegram.org, legal@telegram.org, support@telegram.org,sticker@telegram.org, stopCA@telegram.org, recover@telegram.org, DMCA@telegram.org, sms@telegram.org, dmca@telegram.org.
13:29:47
Письмо от gera.madara@mail.ru успешно отправлено на Abuse@telegram.org, spam@telegram.org, security@telegram.org, legal@telegram.org, support@telegram.org,sticker@telegram.org, stopCA@telegram.org, recover@telegram.org, DMCA@telegram.org, sms@telegram.org, dmca@telegram.org.
13:29:47
Письмо от gera.madara@mail.ru успешно отправлено на Abuse@telegram.org, spam@telegram.org, security@telegram.org, legal@telegram.org, support@telegram.org,sticker@telegram.org, stopCA@telegram.org, recover@telegram.org, DMCA@telegram.org, sms@telegram.org, dmca@telegram.org.
13:29:49
Письмо от gera.madara@mail.ru успешно отправлено на Abuse@telegram.org, spam@telegram.org, security@telegram.org, legal@telegram.org, support@telegram.org,sticker@telegram.org, stopCA@telegram.org, recover@telegram.org, DMCA@telegram.org, sms@telegram.org, dmca@telegram.org.
13:29:50
Письмо от gera.madara@mail.ru успешно отправлено на Abuse@telegram.org, spam@telegram.org, security@telegram.org, legal@telegram.org, support@telegram.org,sticker@telegram.org, stopCA@telegram.org, recover@telegram.org, DMCA@telegram.org, sms@telegram.org, dmca@telegram.org.
13:29:52
Письмо от gera.madara@mail.ru успешно отправлено на Abuse@telegram.org, spam@telegram.org, security@telegram.org, legal@telegram.org, support@telegram.org,sticker@telegram.org, stopCA@telegram.org, recover@telegram.org, DMCA@telegram.org, sms@telegram.org, dmca@telegram.org.
13:29:52
Письмо от gera.madara@mail.ru успешно отправлено на Abuse@telegram.org, spam@telegram.org, security@telegram.org, legal@telegram.org, support@telegram.org,sticker@telegram.org, stopCA@telegram.org, recover@telegram.org, DMCA@telegram.org, sms@telegram.org, dmca@telegram.org.
13:29:54
Письмо от gera.madara@mail.ru успешно отправлено на Abuse@telegram.org, spam@telegram.org, security@telegram.org, legal@telegram.org, support@telegram.org,sticker@telegram.org, stopCA@telegram.org, recover@telegram.org, DMCA@telegram.org, sms@telegram.org, dmca@telegram.org.
Письмо не отправлено по причине: (451, b'Ratelimit exceeded for mailbox gera.madara@mail.ru. Try again later.')
Письмо не отправлено по причине: (451, b'Ratelimit exceeded for mailbox gera.madara@mail.ru. Try again later.')
Письмо не отправлено по причине: (451, b'Ratelimit exceeded for mailbox gera.madara@mail.ru. Try again later.')
Письмо не отправлено по причине: (451, b'Ratelimit exceeded for mailbox gera.madara@mail.ru. Try again later.')
Письмо не отправлено по причине: (451, b'Ratelimit exceeded for mailbox gera.madara@mail.ru. Try again later.')
Письмо не отправлено по причине: (451, b'Ratelimit exceeded for mailbox gera.madara@mail.ru. Try again later.')
Письмо не отправлено по причине: (451, b'Ratelimit exceeded for mailbox gera.madara@mail.ru. Try again later.')
Письмо не отправлено по причине: (451, b'Ratelimit exceeded for mailbox gera.madara@mail.ru. Try again later.')
Письмо не отправлено по причине: (451, b'Ratelimit exceeded for mailbox gera.madara@mail.ru. Try again later.')
Письмо не отправлено по причине: (451, b'Ratelimit exceeded for mailbox gera.madara@mail.ru. Try again later.')
Письмо не отправлено по причине: (451, b'Ratelimit exceeded for mailbox gera.madara@mail.ru. Try again later.')
Письмо не отправлено по причине: (451, b'Ratelimit exceeded for mailbox gera.madara@mail.ru. Try again later.')
Письмо не отправлено по причине: (451, b'Ratelimit exceeded for mailbox gera.madara@mail.ru. Try again later.')
Письмо не отправлено по причине: (451, b'Ratelimit exceeded for mailbox gera.madara@mail.ru. Try again later.')
Письмо не отправлено по причине: (451, b'Ratelimit exceeded for mailbox gera.madara@mail.ru. Try again later.')
Письмо не отправлено по причине: (451, b'Ratelimit exceeded for mailbox gera.madara@mail.ru. Try again later.')
Письмо не отправлено по причине: (451, b'Ratelimit exceeded for mailbox gera.madara@mail.ru. Try again later.')
Письмо не отправлено по причине: (451, b'Ratelimit exceeded for mailbox gera.madara@mail.ru. Try again later.')
Письмо не отправлено по причине: (451, b'Ratelimit exceeded for mailbox gera.madara@mail.ru. Try again later.')
Письмо не отправлено по причине: (451, b'Ratelimit exceeded for mailbox gera.madara@mail.ru. Try again later.')
Письмо не отправлено по причине: (451, b'Ratelimit exceeded for mailbox gera.madara@mail.ru. Try again later.')
Письмо не отправлено по причине: (451, b'Ratelimit exceeded for mailbox gera.madara@mail.ru. Try again later.')
Письмо не отправлено по причине: (451, b'Ratelimit exceeded for mailbox gera.madara@mail.ru. Try again later.')
Письмо не отправлено по причине: (451, b'Ratelimit exceeded for mailbox gera.madara@mail.ru. Try again later.')
Письмо не отправлено по причине: (451, b'Ratelimit exceeded for mailbox gera.madara@mail.ru. Try again later.')
Письмо не отправлено по причине: (451, b'Ratelimit exceeded for mailbox gera.madara@mail.ru. Try again later.')
Письмо не отправлено по причине: (451, b'Ratelimit exceeded for mailbox gera.madara@mail.ru. Try again later.')
2024-10-12 16:24:44,884 (__init__.py:1241 MainThread) ERROR - TeleBot: "Threaded polling exception: A request to the Telegram API was unsuccessful. Error code: 429. Description: Too Many Requests: retry after 39"
2024-10-12 16:24:44,885 (__init__.py:1243 MainThread) ERROR - TeleBot: "Exception traceback:
Traceback (most recent call last):
  File "/root/venv/lib/python3.12/site-packages/telebot/__init__.py", line 1235, in __threaded_polling
    self.worker_pool.raise_exceptions()
  File "/root/venv/lib/python3.12/site-packages/telebot/util.py", line 150, in raise_exceptions
    raise self.exception_info
  File "/root/venv/lib/python3.12/site-packages/telebot/util.py", line 93, in run
    task(*args, **kwargs)
  File "/root/venv/lib/python3.12/site-packages/telebot/__init__.py", line 8945, in _run_middlewares_and_handler
    result = handler['function'](message)
             ^^^^^^^^^^^^^^^^^^^^^^^^^^^^
  File "/root/snb/main.py", line 340, in process_raid
    bot.send_message(message.chat.id, raid_text)
  File "/root/venv/lib/python3.12/site-packages/telebot/__init__.py", line 1775, in send_message
    apihelper.send_message(
  File "/root/venv/lib/python3.12/site-packages/telebot/apihelper.py", line 273, in send_message
    return _make_request(token, method_url, params=payload, method='post')
           ^^^^^^^^^^^^^^^^^^^^^^^^^^^^^^^^^^^^^^^^^^^^^^^^^^^^^^^^^^^^^^^
  File "/root/venv/lib/python3.12/site-packages/telebot/apihelper.py", line 168, in _make_request
    json_result = _check_result(method_name, result)
                  ^^^^^^^^^^^^^^^^^^^^^^^^^^^^^^^^^^
  File "/root/venv/lib/python3.12/site-packages/telebot/apihelper.py", line 195, in _check_result
    raise ApiTelegramException(method_name, result, result_json)
telebot.apihelper.ApiTelegramException: A request to the Telegram API was unsuccessful. Error code: 429. Description: Too Many Requests: retry after 39
"
2024-10-12 16:27:52,610 (__init__.py:1241 MainThread) ERROR - TeleBot: "Threaded polling exception: A request to the Telegram API was unsuccessful. Error code: 429. Description: Too Many Requests: retry after 38"
2024-10-12 16:27:52,611 (__init__.py:1243 MainThread) ERROR - TeleBot: "Exception traceback:
Traceback (most recent call last):
  File "/root/venv/lib/python3.12/site-packages/telebot/__init__.py", line 1235, in __threaded_polling
    self.worker_pool.raise_exceptions()
  File "/root/venv/lib/python3.12/site-packages/telebot/util.py", line 150, in raise_exceptions
    raise self.exception_info
  File "/root/venv/lib/python3.12/site-packages/telebot/util.py", line 93, in run
    task(*args, **kwargs)
  File "/root/venv/lib/python3.12/site-packages/telebot/__init__.py", line 8945, in _run_middlewares_and_handler
    result = handler['function'](message)
             ^^^^^^^^^^^^^^^^^^^^^^^^^^^^
  File "/root/snb/main.py", line 340, in process_raid
    bot.send_message(message.chat.id, raid_text)
  File "/root/venv/lib/python3.12/site-packages/telebot/__init__.py", line 1775, in send_message
    apihelper.send_message(
  File "/root/venv/lib/python3.12/site-packages/telebot/apihelper.py", line 273, in send_message
    return _make_request(token, method_url, params=payload, method='post')
           ^^^^^^^^^^^^^^^^^^^^^^^^^^^^^^^^^^^^^^^^^^^^^^^^^^^^^^^^^^^^^^^
  File "/root/venv/lib/python3.12/site-packages/telebot/apihelper.py", line 168, in _make_request
    json_result = _check_result(method_name, result)
                  ^^^^^^^^^^^^^^^^^^^^^^^^^^^^^^^^^^
  File "/root/venv/lib/python3.12/site-packages/telebot/apihelper.py", line 195, in _check_result
    raise ApiTelegramException(method_name, result, result_json)
telebot.apihelper.ApiTelegramException: A request to the Telegram API was unsuccessful. Error code: 429. Description: Too Many Requests: retry after 38
"
Письмо не отправлено по причине: (451, b'Ratelimit exceeded for mailbox gera.madara@mail.ru. Try again later.')
Письмо не отправлено по причине: (451, b'Ratelimit exceeded for mailbox gera.madara@mail.ru. Try again later.')
Письмо не отправлено по причине: (451, b'Ratelimit exceeded for mailbox gera.madara@mail.ru. Try again later.')
Письмо не отправлено по причине: (451, b'Ratelimit exceeded for mailbox gera.madara@mail.ru. Try again later.')
Письмо не отправлено по причине: (451, b'Ratelimit exceeded for mailbox gera.madara@mail.ru. Try again later.')
Письмо не отправлено по причине: (451, b'Ratelimit exceeded for mailbox gera.madara@mail.ru. Try again later.')
Письмо не отправлено по причине: (451, b'Ratelimit exceeded for mailbox gera.madara@mail.ru. Try again later.')
Письмо не отправлено по причине: (451, b'Ratelimit exceeded for mailbox gera.madara@mail.ru. Try again later.')
Письмо не отправлено по причине: (451, b'Ratelimit exceeded for mailbox gera.madara@mail.ru. Try again later.')
Письмо не отправлено по причине: (451, b'Ratelimit exceeded for mailbox gera.madara@mail.ru. Try again later.')
Письмо не отправлено по причине: (451, b'Ratelimit exceeded for mailbox gera.madara@mail.ru. Try again later.')
Письмо не отправлено по причине: (451, b'Ratelimit exceeded for mailbox gera.madara@mail.ru. Try again later.')
Письмо не отправлено по причине: (451, b'Ratelimit exceeded for mailbox gera.madara@mail.ru. Try again later.')
Письмо не отправлено по причине: (451, b'Ratelimit exceeded for mailbox gera.madara@mail.ru. Try again later.')
Письмо не отправлено по причине: (451, b'Ratelimit exceeded for mailbox gera.madara@mail.ru. Try again later.')
Письмо не отправлено по причине: (451, b'Ratelimit exceeded for mailbox gera.madara@mail.ru. Try again later.')
Письмо не отправлено по причине: (451, b'Ratelimit exceeded for mailbox gera.madara@mail.ru. Try again later.')
Письмо не отправлено по причине: (451, b'Ratelimit exceeded for mailbox gera.madara@mail.ru. Try again later.')
Письмо не отправлено по причине: (451, b'Ratelimit exceeded for mailbox gera.madara@mail.ru. Try again later.')
Письмо не отправлено по причине: (451, b'Ratelimit exceeded for mailbox gera.madara@mail.ru. Try again later.')
Письмо не отправлено по причине: (451, b'Ratelimit exceeded for mailbox gera.madara@mail.ru. Try again later.')
16:47:27
Письмо от gera.madara@mail.ru успешно отправлено на Abuse@telegram.org, spam@telegram.org, security@telegram.org, legal@telegram.org, support@telegram.org,sticker@telegram.org, stopCA@telegram.org, recover@telegram.org, DMCA@telegram.org, sms@telegram.org, dmca@telegram.org.
16:47:29
Письмо от gera.madara@mail.ru успешно отправлено на Abuse@telegram.org, spam@telegram.org, security@telegram.org, legal@telegram.org, support@telegram.org,sticker@telegram.org, stopCA@telegram.org, recover@telegram.org, DMCA@telegram.org, sms@telegram.org, dmca@telegram.org.
16:47:32
Письмо от gera.madara@mail.ru успешно отправлено на Abuse@telegram.org, spam@telegram.org, security@telegram.org, legal@telegram.org, support@telegram.org,sticker@telegram.org, stopCA@telegram.org, recover@telegram.org, DMCA@telegram.org, sms@telegram.org, dmca@telegram.org.
16:47:34
Письмо от gera.madara@mail.ru успешно отправлено на Abuse@telegram.org, spam@telegram.org, security@telegram.org, legal@telegram.org, support@telegram.org,sticker@telegram.org, stopCA@telegram.org, recover@telegram.org, DMCA@telegram.org, sms@telegram.org, dmca@telegram.org.
16:47:36
Письмо от gera.madara@mail.ru успешно отправлено на Abuse@telegram.org, spam@telegram.org, security@telegram.org, legal@telegram.org, support@telegram.org,sticker@telegram.org, stopCA@telegram.org, recover@telegram.org, DMCA@telegram.org, sms@telegram.org, dmca@telegram.org.
16:47:39
Письмо от gera.madara@mail.ru успешно отправлено на Abuse@telegram.org, spam@telegram.org, security@telegram.org, legal@telegram.org, support@telegram.org,sticker@telegram.org, stopCA@telegram.org, recover@telegram.org, DMCA@telegram.org, sms@telegram.org, dmca@telegram.org.
16:47:41
Письмо от gera.madara@mail.ru успешно отправлено на Abuse@telegram.org, spam@telegram.org, security@telegram.org, legal@telegram.org, support@telegram.org,sticker@telegram.org, stopCA@telegram.org, recover@telegram.org, DMCA@telegram.org, sms@telegram.org, dmca@telegram.org.
16:47:43
Письмо от gera.madara@mail.ru успешно отправлено на Abuse@telegram.org, spam@telegram.org, security@telegram.org, legal@telegram.org, support@telegram.org,sticker@telegram.org, stopCA@telegram.org, recover@telegram.org, DMCA@telegram.org, sms@telegram.org, dmca@telegram.org.
16:47:46
Письмо от gera.madara@mail.ru успешно отправлено на Abuse@telegram.org, spam@telegram.org, security@telegram.org, legal@telegram.org, support@telegram.org,sticker@telegram.org, stopCA@telegram.org, recover@telegram.org, DMCA@telegram.org, sms@telegram.org, dmca@telegram.org.
16:47:48
Письмо от gera.madara@mail.ru успешно отправлено на Abuse@telegram.org, spam@telegram.org, security@telegram.org, legal@telegram.org, support@telegram.org,sticker@telegram.org, stopCA@telegram.org, recover@telegram.org, DMCA@telegram.org, sms@telegram.org, dmca@telegram.org.
16:47:50
Письмо от gera.madara@mail.ru успешно отправлено на Abuse@telegram.org, spam@telegram.org, security@telegram.org, legal@telegram.org, support@telegram.org,sticker@telegram.org, stopCA@telegram.org, recover@telegram.org, DMCA@telegram.org, sms@telegram.org, dmca@telegram.org.
17:00:45
Письмо от gera.madara@mail.ru успешно отправлено на Abuse@telegram.org, spam@telegram.org, security@telegram.org, legal@telegram.org, support@telegram.org,sticker@telegram.org, stopCA@telegram.org, recover@telegram.org, DMCA@telegram.org, sms@telegram.org, dmca@telegram.org.
17:00:47
Письмо от gera.madara@mail.ru успешно отправлено на Abuse@telegram.org, spam@telegram.org, security@telegram.org, legal@telegram.org, support@telegram.org,sticker@telegram.org, stopCA@telegram.org, recover@telegram.org, DMCA@telegram.org, sms@telegram.org, dmca@telegram.org.
17:00:50
Письмо от gera.madara@mail.ru успешно отправлено на Abuse@telegram.org, spam@telegram.org, security@telegram.org, legal@telegram.org, support@telegram.org,sticker@telegram.org, stopCA@telegram.org, recover@telegram.org, DMCA@telegram.org, sms@telegram.org, dmca@telegram.org.
17:00:52
Письмо от gera.madara@mail.ru успешно отправлено на Abuse@telegram.org, spam@telegram.org, security@telegram.org, legal@telegram.org, support@telegram.org,sticker@telegram.org, stopCA@telegram.org, recover@telegram.org, DMCA@telegram.org, sms@telegram.org, dmca@telegram.org.
17:00:55
Письмо от gera.madara@mail.ru успешно отправлено на Abuse@telegram.org, spam@telegram.org, security@telegram.org, legal@telegram.org, support@telegram.org,sticker@telegram.org, stopCA@telegram.org, recover@telegram.org, DMCA@telegram.org, sms@telegram.org, dmca@telegram.org.
17:00:57
2024-10-12 17:04:28,565 (__init__.py:1241 MainThread) ERROR - TeleBot: "Threaded polling exception: A request to the Telegram API was unsuccessful. Error code: 429. Description: Too Many Requests: retry after 38"
2024-10-12 17:04:28,566 (__init__.py:1243 MainThread) ERROR - TeleBot: "Exception traceback:
Traceback (most recent call last):
  File "/root/venv/lib/python3.12/site-packages/telebot/__init__.py", line 1235, in __threaded_polling
    self.worker_pool.raise_exceptions()
  File "/root/venv/lib/python3.12/site-packages/telebot/util.py", line 150, in raise_exceptions
    raise self.exception_info
  File "/root/venv/lib/python3.12/site-packages/telebot/util.py", line 93, in run
    task(*args, **kwargs)
  File "/root/venv/lib/python3.12/site-packages/telebot/__init__.py", line 8945, in _run_middlewares_and_handler
    result = handler['function'](message)
             ^^^^^^^^^^^^^^^^^^^^^^^^^^^^
  File "/root/snb/main.py", line 340, in process_raid
    bot.send_message(message.chat.id, raid_text)
  File "/root/venv/lib/python3.12/site-packages/telebot/__init__.py", line 1775, in send_message
    apihelper.send_message(
  File "/root/venv/lib/python3.12/site-packages/telebot/apihelper.py", line 273, in send_message
    return _make_request(token, method_url, params=payload, method='post')
           ^^^^^^^^^^^^^^^^^^^^^^^^^^^^^^^^^^^^^^^^^^^^^^^^^^^^^^^^^^^^^^^
  File "/root/venv/lib/python3.12/site-packages/telebot/apihelper.py", line 168, in _make_request
    json_result = _check_result(method_name, result)
                  ^^^^^^^^^^^^^^^^^^^^^^^^^^^^^^^^^^
  File "/root/venv/lib/python3.12/site-packages/telebot/apihelper.py", line 195, in _check_result
    raise ApiTelegramException(method_name, result, result_json)
telebot.apihelper.ApiTelegramException: A request to the Telegram API was unsuccessful. Error code: 429. Description: Too Many Requests: retry after 38
"
2024-10-12 17:07:33,866 (__init__.py:1241 MainThread) ERROR - TeleBot: "Threaded polling exception: A request to the Telegram API was unsuccessful. Error code: 429. Description: Too Many Requests: retry after 39"
2024-10-12 17:07:33,867 (__init__.py:1243 MainThread) ERROR - TeleBot: "Exception traceback:
Traceback (most recent call last):
  File "/root/venv/lib/python3.12/site-packages/telebot/__init__.py", line 1235, in __threaded_polling
    self.worker_pool.raise_exceptions()
  File "/root/venv/lib/python3.12/site-packages/telebot/util.py", line 150, in raise_exceptions
    raise self.exception_info
  File "/root/venv/lib/python3.12/site-packages/telebot/util.py", line 93, in run
    task(*args, **kwargs)
  File "/root/venv/lib/python3.12/site-packages/telebot/__init__.py", line 8945, in _run_middlewares_and_handler
    result = handler['function'](message)
             ^^^^^^^^^^^^^^^^^^^^^^^^^^^^
  File "/root/snb/main.py", line 340, in process_raid
    bot.send_message(message.chat.id, raid_text)
  File "/root/venv/lib/python3.12/site-packages/telebot/__init__.py", line 1775, in send_message
    apihelper.send_message(
  File "/root/venv/lib/python3.12/site-packages/telebot/apihelper.py", line 273, in send_message
    return _make_request(token, method_url, params=payload, method='post')
           ^^^^^^^^^^^^^^^^^^^^^^^^^^^^^^^^^^^^^^^^^^^^^^^^^^^^^^^^^^^^^^^
  File "/root/venv/lib/python3.12/site-packages/telebot/apihelper.py", line 168, in _make_request
    json_result = _check_result(method_name, result)
                  ^^^^^^^^^^^^^^^^^^^^^^^^^^^^^^^^^^
  File "/root/venv/lib/python3.12/site-packages/telebot/apihelper.py", line 195, in _check_result
    raise ApiTelegramException(method_name, result, result_json)
telebot.apihelper.ApiTelegramException: A request to the Telegram API was unsuccessful. Error code: 429. Description: Too Many Requests: retry after 39
"
2024-10-12 17:10:21,618 (__init__.py:1241 MainThread) ERROR - TeleBot: "Threaded polling exception: A request to the Telegram API was unsuccessful. Error code: 429. Description: Too Many Requests: retry after 42"
2024-10-12 17:10:21,619 (__init__.py:1243 MainThread) ERROR - TeleBot: "Exception traceback:
Traceback (most recent call last):
  File "/root/venv/lib/python3.12/site-packages/telebot/__init__.py", line 1235, in __threaded_polling
    self.worker_pool.raise_exceptions()
  File "/root/venv/lib/python3.12/site-packages/telebot/util.py", line 150, in raise_exceptions
    raise self.exception_info
  File "/root/venv/lib/python3.12/site-packages/telebot/util.py", line 93, in run
    task(*args, **kwargs)
  File "/root/venv/lib/python3.12/site-packages/telebot/__init__.py", line 8945, in _run_middlewares_and_handler
    result = handler['function'](message)
             ^^^^^^^^^^^^^^^^^^^^^^^^^^^^
  File "/root/snb/main.py", line 340, in process_raid
    bot.send_message(message.chat.id, raid_text)
  File "/root/venv/lib/python3.12/site-packages/telebot/__init__.py", line 1775, in send_message
    apihelper.send_message(
  File "/root/venv/lib/python3.12/site-packages/telebot/apihelper.py", line 273, in send_message
    return _make_request(token, method_url, params=payload, method='post')
           ^^^^^^^^^^^^^^^^^^^^^^^^^^^^^^^^^^^^^^^^^^^^^^^^^^^^^^^^^^^^^^^
  File "/root/venv/lib/python3.12/site-packages/telebot/apihelper.py", line 168, in _make_request
    json_result = _check_result(method_name, result)
                  ^^^^^^^^^^^^^^^^^^^^^^^^^^^^^^^^^^
  File "/root/venv/lib/python3.12/site-packages/telebot/apihelper.py", line 195, in _check_result
    raise ApiTelegramException(method_name, result, result_json)
telebot.apihelper.ApiTelegramException: A request to the Telegram API was unsuccessful. Error code: 429. Description: Too Many Requests: retry after 42
"
2024-10-12 17:11:27,591 (__init__.py:1241 MainThread) ERROR - TeleBot: "Threaded polling exception: A request to the Telegram API was unsuccessful. Error code: 429. Description: Too Many Requests: retry after 36"
2024-10-12 17:11:27,592 (__init__.py:1243 MainThread) ERROR - TeleBot: "Exception traceback:
Traceback (most recent call last):
  File "/root/venv/lib/python3.12/site-packages/telebot/__init__.py", line 1235, in __threaded_polling
    self.worker_pool.raise_exceptions()
  File "/root/venv/lib/python3.12/site-packages/telebot/util.py", line 150, in raise_exceptions
    raise self.exception_info
  File "/root/venv/lib/python3.12/site-packages/telebot/util.py", line 93, in run
    task(*args, **kwargs)
  File "/root/venv/lib/python3.12/site-packages/telebot/__init__.py", line 8945, in _run_middlewares_and_handler
    result = handler['function'](message)
             ^^^^^^^^^^^^^^^^^^^^^^^^^^^^
  File "/root/snb/main.py", line 340, in process_raid
    bot.send_message(message.chat.id, raid_text)
  File "/root/venv/lib/python3.12/site-packages/telebot/__init__.py", line 1775, in send_message
    apihelper.send_message(
  File "/root/venv/lib/python3.12/site-packages/telebot/apihelper.py", line 273, in send_message
    return _make_request(token, method_url, params=payload, method='post')
           ^^^^^^^^^^^^^^^^^^^^^^^^^^^^^^^^^^^^^^^^^^^^^^^^^^^^^^^^^^^^^^^
  File "/root/venv/lib/python3.12/site-packages/telebot/apihelper.py", line 168, in _make_request
    json_result = _check_result(method_name, result)
                  ^^^^^^^^^^^^^^^^^^^^^^^^^^^^^^^^^^
  File "/root/venv/lib/python3.12/site-packages/telebot/apihelper.py", line 195, in _check_result
    raise ApiTelegramException(method_name, result, result_json)
telebot.apihelper.ApiTelegramException: A request to the Telegram API was unsuccessful. Error code: 429. Description: Too Many Requests: retry after 36
"
2024-10-12 17:12:26,279 (__init__.py:1241 MainThread) ERROR - TeleBot: "Threaded polling exception: A request to the Telegram API was unsuccessful. Error code: 429. Description: Too Many Requests: retry after 40"
2024-10-12 17:12:26,280 (__init__.py:1243 MainThread) ERROR - TeleBot: "Exception traceback:
Traceback (most recent call last):
  File "/root/venv/lib/python3.12/site-packages/telebot/__init__.py", line 1235, in __threaded_polling
    self.worker_pool.raise_exceptions()
  File "/root/venv/lib/python3.12/site-packages/telebot/util.py", line 150, in raise_exceptions
    raise self.exception_info
  File "/root/venv/lib/python3.12/site-packages/telebot/util.py", line 93, in run
    task(*args, **kwargs)
  File "/root/venv/lib/python3.12/site-packages/telebot/__init__.py", line 8945, in _run_middlewares_and_handler
    result = handler['function'](message)
             ^^^^^^^^^^^^^^^^^^^^^^^^^^^^
  File "/root/snb/main.py", line 340, in process_raid
    bot.send_message(message.chat.id, raid_text)
  File "/root/venv/lib/python3.12/site-packages/telebot/__init__.py", line 1775, in send_message
    apihelper.send_message(
  File "/root/venv/lib/python3.12/site-packages/telebot/apihelper.py", line 273, in send_message
    return _make_request(token, method_url, params=payload, method='post')
           ^^^^^^^^^^^^^^^^^^^^^^^^^^^^^^^^^^^^^^^^^^^^^^^^^^^^^^^^^^^^^^^
  File "/root/venv/lib/python3.12/site-packages/telebot/apihelper.py", line 168, in _make_request
    json_result = _check_result(method_name, result)
                  ^^^^^^^^^^^^^^^^^^^^^^^^^^^^^^^^^^
  File "/root/venv/lib/python3.12/site-packages/telebot/apihelper.py", line 195, in _check_result
    raise ApiTelegramException(method_name, result, result_json)
telebot.apihelper.ApiTelegramException: A request to the Telegram API was unsuccessful. Error code: 429. Description: Too Many Requests: retry after 40
"
2024-10-12 17:22:22,835 (__init__.py:1241 MainThread) ERROR - TeleBot: "Threaded polling exception: A request to the Telegram API was unsuccessful. Error code: 429. Description: Too Many Requests: retry after 39"
2024-10-12 17:22:22,836 (__init__.py:1243 MainThread) ERROR - TeleBot: "Exception traceback:
Traceback (most recent call last):
  File "/root/venv/lib/python3.12/site-packages/telebot/__init__.py", line 1235, in __threaded_polling
    self.worker_pool.raise_exceptions()
  File "/root/venv/lib/python3.12/site-packages/telebot/util.py", line 150, in raise_exceptions
    raise self.exception_info
  File "/root/venv/lib/python3.12/site-packages/telebot/util.py", line 93, in run
    task(*args, **kwargs)
  File "/root/venv/lib/python3.12/site-packages/telebot/__init__.py", line 8945, in _run_middlewares_and_handler
    result = handler['function'](message)
             ^^^^^^^^^^^^^^^^^^^^^^^^^^^^
  File "/root/snb/main.py", line 340, in process_raid
    bot.send_message(message.chat.id, raid_text)
  File "/root/venv/lib/python3.12/site-packages/telebot/__init__.py", line 1775, in send_message
    apihelper.send_message(
  File "/root/venv/lib/python3.12/site-packages/telebot/apihelper.py", line 273, in send_message
    return _make_request(token, method_url, params=payload, method='post')
           ^^^^^^^^^^^^^^^^^^^^^^^^^^^^^^^^^^^^^^^^^^^^^^^^^^^^^^^^^^^^^^^
  File "/root/venv/lib/python3.12/site-packages/telebot/apihelper.py", line 168, in _make_request
    json_result = _check_result(method_name, result)
                  ^^^^^^^^^^^^^^^^^^^^^^^^^^^^^^^^^^
  File "/root/venv/lib/python3.12/site-packages/telebot/apihelper.py", line 195, in _check_result
    raise ApiTelegramException(method_name, result, result_json)
telebot.apihelper.ApiTelegramException: A request to the Telegram API was unsuccessful. Error code: 429. Description: Too Many Requests: retry after 39
"
2024-10-12 17:23:29,077 (__init__.py:1241 MainThread) ERROR - TeleBot: "Threaded polling exception: A request to the Telegram API was unsuccessful. Error code: 429. Description: Too Many Requests: retry after 35"
2024-10-12 17:23:29,079 (__init__.py:1243 MainThread) ERROR - TeleBot: "Exception traceback:
Traceback (most recent call last):
  File "/root/venv/lib/python3.12/site-packages/telebot/__init__.py", line 1235, in __threaded_polling
    self.worker_pool.raise_exceptions()
  File "/root/venv/lib/python3.12/site-packages/telebot/util.py", line 150, in raise_exceptions
    raise self.exception_info
  File "/root/venv/lib/python3.12/site-packages/telebot/util.py", line 93, in run
    task(*args, **kwargs)
  File "/root/venv/lib/python3.12/site-packages/telebot/__init__.py", line 8945, in _run_middlewares_and_handler
    result = handler['function'](message)
             ^^^^^^^^^^^^^^^^^^^^^^^^^^^^
  File "/root/snb/main.py", line 340, in process_raid
    bot.send_message(message.chat.id, raid_text)
  File "/root/venv/lib/python3.12/site-packages/telebot/__init__.py", line 1775, in send_message
    apihelper.send_message(
  File "/root/venv/lib/python3.12/site-packages/telebot/apihelper.py", line 273, in send_message
    return _make_request(token, method_url, params=payload, method='post')
           ^^^^^^^^^^^^^^^^^^^^^^^^^^^^^^^^^^^^^^^^^^^^^^^^^^^^^^^^^^^^^^^
  File "/root/venv/lib/python3.12/site-packages/telebot/apihelper.py", line 168, in _make_request
    json_result = _check_result(method_name, result)
                  ^^^^^^^^^^^^^^^^^^^^^^^^^^^^^^^^^^
  File "/root/venv/lib/python3.12/site-packages/telebot/apihelper.py", line 195, in _check_result
    raise ApiTelegramException(method_name, result, result_json)
telebot.apihelper.ApiTelegramException: A request to the Telegram API was unsuccessful. Error code: 429. Description: Too Many Requests: retry after 35
"
2024-10-12 17:24:25,771 (__init__.py:1241 MainThread) ERROR - TeleBot: "Threaded polling exception: A request to the Telegram API was unsuccessful. Error code: 429. Description: Too Many Requests: retry after 42"
2024-10-12 17:24:25,772 (__init__.py:1243 MainThread) ERROR - TeleBot: "Exception traceback:
Traceback (most recent call last):
  File "/root/venv/lib/python3.12/site-packages/telebot/__init__.py", line 1235, in __threaded_polling
    self.worker_pool.raise_exceptions()
  File "/root/venv/lib/python3.12/site-packages/telebot/util.py", line 150, in raise_exceptions
    raise self.exception_info
  File "/root/venv/lib/python3.12/site-packages/telebot/util.py", line 93, in run
    task(*args, **kwargs)
  File "/root/venv/lib/python3.12/site-packages/telebot/__init__.py", line 8945, in _run_middlewares_and_handler
    result = handler['function'](message)
             ^^^^^^^^^^^^^^^^^^^^^^^^^^^^
  File "/root/snb/main.py", line 340, in process_raid
    bot.send_message(message.chat.id, raid_text)
  File "/root/venv/lib/python3.12/site-packages/telebot/__init__.py", line 1775, in send_message
    apihelper.send_message(
  File "/root/venv/lib/python3.12/site-packages/telebot/apihelper.py", line 273, in send_message
    return _make_request(token, method_url, params=payload, method='post')
           ^^^^^^^^^^^^^^^^^^^^^^^^^^^^^^^^^^^^^^^^^^^^^^^^^^^^^^^^^^^^^^^
  File "/root/venv/lib/python3.12/site-packages/telebot/apihelper.py", line 168, in _make_request
    json_result = _check_result(method_name, result)
                  ^^^^^^^^^^^^^^^^^^^^^^^^^^^^^^^^^^
  File "/root/venv/lib/python3.12/site-packages/telebot/apihelper.py", line 195, in _check_result
    raise ApiTelegramException(method_name, result, result_json)
telebot.apihelper.ApiTelegramException: A request to the Telegram API was unsuccessful. Error code: 429. Description: Too Many Requests: retry after 42
"
2024-10-12 17:27:03,550 (__init__.py:1241 MainThread) ERROR - TeleBot: "Threaded polling exception: A request to the Telegram API was unsuccessful. Error code: 429. Description: Too Many Requests: retry after 39"
2024-10-12 17:27:03,551 (__init__.py:1243 MainThread) ERROR - TeleBot: "Exception traceback:
Traceback (most recent call last):
  File "/root/venv/lib/python3.12/site-packages/telebot/__init__.py", line 1235, in __threaded_polling
    self.worker_pool.raise_exceptions()
  File "/root/venv/lib/python3.12/site-packages/telebot/util.py", line 150, in raise_exceptions
    raise self.exception_info
  File "/root/venv/lib/python3.12/site-packages/telebot/util.py", line 93, in run
    task(*args, **kwargs)
  File "/root/venv/lib/python3.12/site-packages/telebot/__init__.py", line 8945, in _run_middlewares_and_handler
    result = handler['function'](message)
             ^^^^^^^^^^^^^^^^^^^^^^^^^^^^
  File "/root/snb/main.py", line 340, in process_raid
    bot.send_message(message.chat.id, raid_text)
  File "/root/venv/lib/python3.12/site-packages/telebot/__init__.py", line 1775, in send_message
    apihelper.send_message(
  File "/root/venv/lib/python3.12/site-packages/telebot/apihelper.py", line 273, in send_message
    return _make_request(token, method_url, params=payload, method='post')
           ^^^^^^^^^^^^^^^^^^^^^^^^^^^^^^^^^^^^^^^^^^^^^^^^^^^^^^^^^^^^^^^
  File "/root/venv/lib/python3.12/site-packages/telebot/apihelper.py", line 168, in _make_request
    json_result = _check_result(method_name, result)
                  ^^^^^^^^^^^^^^^^^^^^^^^^^^^^^^^^^^
  File "/root/venv/lib/python3.12/site-packages/telebot/apihelper.py", line 195, in _check_result
    raise ApiTelegramException(method_name, result, result_json)
telebot.apihelper.ApiTelegramException: A request to the Telegram API was unsuccessful. Error code: 429. Description: Too Many Requests: retry after 39
"
2024-10-12 17:28:03,885 (__init__.py:1241 MainThread) ERROR - TeleBot: "Threaded polling exception: A request to the Telegram API was unsuccessful. Error code: 429. Description: Too Many Requests: retry after 39"
2024-10-12 17:28:03,886 (__init__.py:1243 MainThread) ERROR - TeleBot: "Exception traceback:
Traceback (most recent call last):
  File "/root/venv/lib/python3.12/site-packages/telebot/__init__.py", line 1235, in __threaded_polling
    self.worker_pool.raise_exceptions()
  File "/root/venv/lib/python3.12/site-packages/telebot/util.py", line 150, in raise_exceptions
    raise self.exception_info
  File "/root/venv/lib/python3.12/site-packages/telebot/util.py", line 93, in run
    task(*args, **kwargs)
  File "/root/venv/lib/python3.12/site-packages/telebot/__init__.py", line 8945, in _run_middlewares_and_handler
    result = handler['function'](message)
             ^^^^^^^^^^^^^^^^^^^^^^^^^^^^
  File "/root/snb/main.py", line 340, in process_raid
    bot.send_message(message.chat.id, raid_text)
  File "/root/venv/lib/python3.12/site-packages/telebot/__init__.py", line 1775, in send_message
    apihelper.send_message(
  File "/root/venv/lib/python3.12/site-packages/telebot/apihelper.py", line 273, in send_message
    return _make_request(token, method_url, params=payload, method='post')
           ^^^^^^^^^^^^^^^^^^^^^^^^^^^^^^^^^^^^^^^^^^^^^^^^^^^^^^^^^^^^^^^
  File "/root/venv/lib/python3.12/site-packages/telebot/apihelper.py", line 168, in _make_request
    json_result = _check_result(method_name, result)
                  ^^^^^^^^^^^^^^^^^^^^^^^^^^^^^^^^^^
  File "/root/venv/lib/python3.12/site-packages/telebot/apihelper.py", line 195, in _check_result
    raise ApiTelegramException(method_name, result, result_json)
telebot.apihelper.ApiTelegramException: A request to the Telegram API was unsuccessful. Error code: 429. Description: Too Many Requests: retry after 39
"
2024-10-13 01:10:50,948 (__init__.py:1241 MainThread) ERROR - TeleBot: "Threaded polling exception: A request to the Telegram API was unsuccessful. Error code: 429. Description: Too Many Requests: retry after 5"
2024-10-13 01:10:50,949 (__init__.py:1243 MainThread) ERROR - TeleBot: "Exception traceback:
Traceback (most recent call last):
  File "/root/venv/lib/python3.12/site-packages/telebot/__init__.py", line 1235, in __threaded_polling
    self.worker_pool.raise_exceptions()
  File "/root/venv/lib/python3.12/site-packages/telebot/util.py", line 150, in raise_exceptions
    raise self.exception_info
  File "/root/venv/lib/python3.12/site-packages/telebot/util.py", line 93, in run
    task(*args, **kwargs)
  File "/root/venv/lib/python3.12/site-packages/telebot/__init__.py", line 8945, in _run_middlewares_and_handler
    result = handler['function'](message)
             ^^^^^^^^^^^^^^^^^^^^^^^^^^^^
  File "/root/snb/main.py", line 162, in check_status
    bot.send_message(user_id, f"Вы не оплатили счет!")
  File "/root/venv/lib/python3.12/site-packages/telebot/__init__.py", line 1775, in send_message
    apihelper.send_message(
  File "/root/venv/lib/python3.12/site-packages/telebot/apihelper.py", line 273, in send_message
    return _make_request(token, method_url, params=payload, method='post')
           ^^^^^^^^^^^^^^^^^^^^^^^^^^^^^^^^^^^^^^^^^^^^^^^^^^^^^^^^^^^^^^^
  File "/root/venv/lib/python3.12/site-packages/telebot/apihelper.py", line 168, in _make_request
    json_result = _check_result(method_name, result)
                  ^^^^^^^^^^^^^^^^^^^^^^^^^^^^^^^^^^
  File "/root/venv/lib/python3.12/site-packages/telebot/apihelper.py", line 195, in _check_result
    raise ApiTelegramException(method_name, result, result_json)
telebot.apihelper.ApiTelegramException: A request to the Telegram API was unsuccessful. Error code: 429. Description: Too Many Requests: retry after 5
"
2024-10-13 01:10:57,456 (__init__.py:1241 MainThread) ERROR - TeleBot: "Threaded polling exception: A request to the Telegram API was unsuccessful. Error code: 502. Description: Bad Gateway"
2024-10-13 01:10:57,457 (__init__.py:1243 MainThread) ERROR - TeleBot: "Exception traceback:
Traceback (most recent call last):
  File "/root/venv/lib/python3.12/site-packages/telebot/__init__.py", line 1234, in __threaded_polling
    polling_thread.raise_exceptions()
  File "/root/venv/lib/python3.12/site-packages/telebot/util.py", line 111, in raise_exceptions
    raise self.exception_info
  File "/root/venv/lib/python3.12/site-packages/telebot/util.py", line 93, in run
    task(*args, **kwargs)
  File "/root/venv/lib/python3.12/site-packages/telebot/__init__.py", line 688, in __retrieve_updates
    updates = self.get_updates(offset=(self.last_update_id + 1),
             ^^^^^^^^^^^^^^^^^^^^^^^^^^^^^^^^^^^^^^^^^^^^^^^^^^
  File "/root/venv/lib/python3.12/site-packages/telebot/__init__.py", line 660, in get_updates
    json_updates = apihelper.get_updates(
                   ^^^^^^^^^^^^^^^^^^^^^^
  File "/root/venv/lib/python3.12/site-packages/telebot/apihelper.py", line 330, in get_updates
    return _make_request(token, method_url, params=payload)
           ^^^^^^^^^^^^^^^^^^^^^^^^^^^^^^^^^^^^^^^^^^^^^^^^
  File "/root/venv/lib/python3.12/site-packages/telebot/apihelper.py", line 168, in _make_request
    json_result = _check_result(method_name, result)
                  ^^^^^^^^^^^^^^^^^^^^^^^^^^^^^^^^^^
  File "/root/venv/lib/python3.12/site-packages/telebot/apihelper.py", line 195, in _check_result
    raise ApiTelegramException(method_name, result, result_json)
telebot.apihelper.ApiTelegramException: A request to the Telegram API was unsuccessful. Error code: 502. Description: Bad Gateway
"
2024-10-13 01:10:57,974 (__init__.py:1241 MainThread) ERROR - TeleBot: "Threaded polling exception: A request to the Telegram API was unsuccessful. Error code: 502. Description: Bad Gateway"
2024-10-13 01:10:57,975 (__init__.py:1243 MainThread) ERROR - TeleBot: "Exception traceback:
Traceback (most recent call last):
  File "/root/venv/lib/python3.12/site-packages/telebot/__init__.py", line 1234, in __threaded_polling
    polling_thread.raise_exceptions()
  File "/root/venv/lib/python3.12/site-packages/telebot/util.py", line 111, in raise_exceptions
    raise self.exception_info
  File "/root/venv/lib/python3.12/site-packages/telebot/util.py", line 93, in run
    task(*args, **kwargs)
  File "/root/venv/lib/python3.12/site-packages/telebot/__init__.py", line 688, in __retrieve_updates
    updates = self.get_updates(offset=(self.last_update_id + 1),
             ^^^^^^^^^^^^^^^^^^^^^^^^^^^^^^^^^^^^^^^^^^^^^^^^^^
  File "/root/venv/lib/python3.12/site-packages/telebot/__init__.py", line 660, in get_updates
    json_updates = apihelper.get_updates(
                   ^^^^^^^^^^^^^^^^^^^^^^
  File "/root/venv/lib/python3.12/site-packages/telebot/apihelper.py", line 330, in get_updates
    return _make_request(token, method_url, params=payload)
           ^^^^^^^^^^^^^^^^^^^^^^^^^^^^^^^^^^^^^^^^^^^^^^^^
  File "/root/venv/lib/python3.12/site-packages/telebot/apihelper.py", line 168, in _make_request
    json_result = _check_result(method_name, result)
                  ^^^^^^^^^^^^^^^^^^^^^^^^^^^^^^^^^^
  File "/root/venv/lib/python3.12/site-packages/telebot/apihelper.py", line 195, in _check_result
    raise ApiTelegramException(method_name, result, result_json)
telebot.apihelper.ApiTelegramException: A request to the Telegram API was unsuccessful. Error code: 502. Description: Bad Gateway
"
2024-10-13 01:10:58,991 (__init__.py:1241 MainThread) ERROR - TeleBot: "Threaded polling exception: A request to the Telegram API was unsuccessful. Error code: 502. Description: Bad Gateway"
2024-10-13 01:10:58,992 (__init__.py:1243 MainThread) ERROR - TeleBot: "Exception traceback:
Traceback (most recent call last):
  File "/root/venv/lib/python3.12/site-packages/telebot/__init__.py", line 1234, in __threaded_polling
    polling_thread.raise_exceptions()
  File "/root/venv/lib/python3.12/site-packages/telebot/util.py", line 111, in raise_exceptions
    raise self.exception_info
  File "/root/venv/lib/python3.12/site-packages/telebot/util.py", line 93, in run
    task(*args, **kwargs)
  File "/root/venv/lib/python3.12/site-packages/telebot/__init__.py", line 688, in __retrieve_updates
    updates = self.get_updates(offset=(self.last_update_id + 1),
             ^^^^^^^^^^^^^^^^^^^^^^^^^^^^^^^^^^^^^^^^^^^^^^^^^^
  File "/root/venv/lib/python3.12/site-packages/telebot/__init__.py", line 660, in get_updates
    json_updates = apihelper.get_updates(
                   ^^^^^^^^^^^^^^^^^^^^^^
  File "/root/venv/lib/python3.12/site-packages/telebot/apihelper.py", line 330, in get_updates
    return _make_request(token, method_url, params=payload)
           ^^^^^^^^^^^^^^^^^^^^^^^^^^^^^^^^^^^^^^^^^^^^^^^^
  File "/root/venv/lib/python3.12/site-packages/telebot/apihelper.py", line 168, in _make_request
    json_result = _check_result(method_name, result)
                  ^^^^^^^^^^^^^^^^^^^^^^^^^^^^^^^^^^
  File "/root/venv/lib/python3.12/site-packages/telebot/apihelper.py", line 195, in _check_result
    raise ApiTelegramException(method_name, result, result_json)
telebot.apihelper.ApiTelegramException: A request to the Telegram API was unsuccessful. Error code: 502. Description: Bad Gateway
"
2024-10-13 01:11:01,008 (__init__.py:1241 MainThread) ERROR - TeleBot: "Threaded polling exception: A request to the Telegram API was unsuccessful. Error code: 502. Description: Bad Gateway"
2024-10-13 01:11:01,009 (__init__.py:1243 MainThread) ERROR - TeleBot: "Exception traceback:
Traceback (most recent call last):
  File "/root/venv/lib/python3.12/site-packages/telebot/__init__.py", line 1234, in __threaded_polling
    polling_thread.raise_exceptions()
  File "/root/venv/lib/python3.12/site-packages/telebot/util.py", line 111, in raise_exceptions
    raise self.exception_info
  File "/root/venv/lib/python3.12/site-packages/telebot/util.py", line 93, in run
    task(*args, **kwargs)
  File "/root/venv/lib/python3.12/site-packages/telebot/__init__.py", line 688, in __retrieve_updates
    updates = self.get_updates(offset=(self.last_update_id + 1),
             ^^^^^^^^^^^^^^^^^^^^^^^^^^^^^^^^^^^^^^^^^^^^^^^^^^
  File "/root/venv/lib/python3.12/site-packages/telebot/__init__.py", line 660, in get_updates
    json_updates = apihelper.get_updates(
                   ^^^^^^^^^^^^^^^^^^^^^^
  File "/root/venv/lib/python3.12/site-packages/telebot/apihelper.py", line 330, in get_updates
    return _make_request(token, method_url, params=payload)
           ^^^^^^^^^^^^^^^^^^^^^^^^^^^^^^^^^^^^^^^^^^^^^^^^
  File "/root/venv/lib/python3.12/site-packages/telebot/apihelper.py", line 168, in _make_request
    json_result = _check_result(method_name, result)
                  ^^^^^^^^^^^^^^^^^^^^^^^^^^^^^^^^^^
  File "/root/venv/lib/python3.12/site-packages/telebot/apihelper.py", line 195, in _check_result
    raise ApiTelegramException(method_name, result, result_json)
telebot.apihelper.ApiTelegramException: A request to the Telegram API was unsuccessful. Error code: 502. Description: Bad Gateway
"
Traceback (most recent call last):
  File "/root/venv/lib/python3.12/site-packages/urllib3/connectionpool.py", line 536, in _make_request
    response = conn.getresponse()
               ^^^^^^^^^^^^^^^^^^
  File "/root/venv/lib/python3.12/site-packages/urllib3/connection.py", line 507, in getresponse
    httplib_response = super().getresponse()
                       ^^^^^^^^^^^^^^^^^^^^^
  File "/usr/lib/python3.12/http/client.py", line 1428, in getresponse
    response.begin()
  File "/usr/lib/python3.12/http/client.py", line 331, in begin
    version, status, reason = self._read_status()
                              ^^^^^^^^^^^^^^^^^^^
  File "/usr/lib/python3.12/http/client.py", line 292, in _read_status
    line = str(self.fp.readline(_MAXLINE + 1), "iso-8859-1")
               ^^^^^^^^^^^^^^^^^^^^^^^^^^^^^^
  File "/usr/lib/python3.12/socket.py", line 707, in readinto
    return self._sock.recv_into(b)
           ^^^^^^^^^^^^^^^^^^^^^^^
  File "/usr/lib/python3.12/ssl.py", line 1252, in recv_into
    return self.read(nbytes, buffer)
           ^^^^^^^^^^^^^^^^^^^^^^^^^
  File "/usr/lib/python3.12/ssl.py", line 1104, in read
    return self._sslobj.read(len, buffer)
           ^^^^^^^^^^^^^^^^^^^^^^^^^^^^^^
TimeoutError: The read operation timed out

The above exception was the direct cause of the following exception:

Traceback (most recent call last):
  File "/root/venv/lib/python3.12/site-packages/requests/adapters.py", line 667, in send
    resp = conn.urlopen(
           ^^^^^^^^^^^^^
  File "/root/venv/lib/python3.12/site-packages/urllib3/connectionpool.py", line 843, in urlopen
    retries = retries.increment(
              ^^^^^^^^^^^^^^^^^^
  File "/root/venv/lib/python3.12/site-packages/urllib3/util/retry.py", line 474, in increment
    raise reraise(type(error), error, _stacktrace)
          ^^^^^^^^^^^^^^^^^^^^^^^^^^^^^^^^^^^^^^^^
  File "/root/venv/lib/python3.12/site-packages/urllib3/util/util.py", line 39, in reraise
    raise value
  File "/root/venv/lib/python3.12/site-packages/urllib3/connectionpool.py", line 789, in urlopen
    response = self._make_request(
               ^^^^^^^^^^^^^^^^^^^
  File "/root/venv/lib/python3.12/site-packages/urllib3/connectionpool.py", line 538, in _make_request
    self._raise_timeout(err=e, url=url, timeout_value=read_timeout)
  File "/root/venv/lib/python3.12/site-packages/urllib3/connectionpool.py", line 369, in _raise_timeout
    raise ReadTimeoutError(
urllib3.exceptions.ReadTimeoutError: HTTPSConnectionPool(host='api.telegram.org', port=443): Read timed out. (read timeout=25)

During handling of the above exception, another exception occurred:

Traceback (most recent call last):
  File "/root/snb/main.py", line 502, in <module>
    bot.polling(none_stop=True)
  File "/root/venv/lib/python3.12/site-packages/telebot/__init__.py", line 1198, in polling
    self.__threaded_polling(non_stop=non_stop, interval=interval, timeout=timeout, long_polling_timeout=long_polling_timeout,
  File "/root/venv/lib/python3.12/site-packages/telebot/__init__.py", line 1273, in __threaded_polling
    raise e
  File "/root/venv/lib/python3.12/site-packages/telebot/__init__.py", line 1234, in __threaded_polling
    polling_thread.raise_exceptions()
  File "/root/venv/lib/python3.12/site-packages/telebot/util.py", line 111, in raise_exceptions
    raise self.exception_info
  File "/root/venv/lib/python3.12/site-packages/telebot/util.py", line 93, in run
    task(*args, **kwargs)
  File "/root/venv/lib/python3.12/site-packages/telebot/__init__.py", line 688, in __retrieve_updates
    updates = self.get_updates(offset=(self.last_update_id + 1), 
              ^^^^^^^^^^^^^^^^^^^^^^^^^^^^^^^^^^^^^^^^^^^^^^^^^^
  File "/root/venv/lib/python3.12/site-packages/telebot/__init__.py", line 660, in get_updates
    json_updates = apihelper.get_updates(
                   ^^^^^^^^^^^^^^^^^^^^^^
  File "/root/venv/lib/python3.12/site-packages/telebot/apihelper.py", line 330, in get_updates
    return _make_request(token, method_url, params=payload)
           ^^^^^^^^^^^^^^^^^^^^^^^^^^^^^^^^^^^^^^^^^^^^^^^^
  File "/root/venv/lib/python3.12/site-packages/telebot/apihelper.py", line 162, in _make_request
    result = _get_req_session().request(
             ^^^^^^^^^^^^^^^^^^^^^^^^^^^
  File "/root/venv/lib/python3.12/site-packages/requests/sessions.py", line 589, in request
    resp = self.send(prep, **send_kwargs)
           ^^^^^^^^^^^^^^^^^^^^^^^^^^^^^^
  File "/root/venv/lib/python3.12/site-packages/requests/sessions.py", line 703, in send
    r = adapter.send(request, **kwargs)
        ^^^^^^^^^^^^^^^^^^^^^^^^^^^^^^^
  File "/root/venv/lib/python3.12/site-packages/requests/adapters.py", line 713, in send
    raise ReadTimeout(e, request=request)
requests.exceptions.ReadTimeout: HTTPSConnectionPool(host='api.telegram.org', port=443): Read timed out. (read timeout=25)
2024-10-13 01:15:57,962 (__init__.py:1241 MainThread) ERROR - TeleBot: "Threaded polling exception: A request to the Telegram API was unsuccessful. Error code: 403. Description: Forbidden: bot was blocked by the user"
2024-10-13 01:15:57,963 (__init__.py:1243 MainThread) ERROR - TeleBot: "Exception traceback:
Traceback (most recent call last):
  File "/root/venv/lib/python3.12/site-packages/telebot/__init__.py", line 1235, in __threaded_polling
    self.worker_pool.raise_exceptions()
  File "/root/venv/lib/python3.12/site-packages/telebot/util.py", line 150, in raise_exceptions
    raise self.exception_info
  File "/root/venv/lib/python3.12/site-packages/telebot/util.py", line 93, in run
    task(*args, **kwargs)
  File "/root/venv/lib/python3.12/site-packages/telebot/__init__.py", line 8945, in _run_middlewares_and_handler
    result = handler['function'](message)
             ^^^^^^^^^^^^^^^^^^^^^^^^^^^^
  File "/root/snb/main.py", line 136, in start
    bot.send_photo(message.chat.id, photo,
  File "/root/venv/lib/python3.12/site-packages/telebot/__init__.py", line 2259, in send_photo
    apihelper.send_photo(
  File "/root/venv/lib/python3.12/site-packages/telebot/apihelper.py", line 527, in send_photo
    return _make_request(token, method_url, params=payload, files=files, method='post')
           ^^^^^^^^^^^^^^^^^^^^^^^^^^^^^^^^^^^^^^^^^^^^^^^^^^^^^^^^^^^^^^^^^^^^^^^^^^^^
  File "/root/venv/lib/python3.12/site-packages/telebot/apihelper.py", line 168, in _make_request
    json_result = _check_result(method_name, result)
                  ^^^^^^^^^^^^^^^^^^^^^^^^^^^^^^^^^^
  File "/root/venv/lib/python3.12/site-packages/telebot/apihelper.py", line 195, in _check_result
    raise ApiTelegramException(method_name, result, result_json)
telebot.apihelper.ApiTelegramException: A request to the Telegram API was unsuccessful. Error code: 403. Description: Forbidden: bot was blocked by the user
"
Traceback (most recent call last):
  File "/root/snb/main.py", line 1, in <module>
    import telebot
ModuleNotFoundError: No module named 'telebot'
16:57:27
Письмо от gera.madara@mail.ru успешно отправлено на Abuse@telegram.org, spam@telegram.org, security@telegram.org, legal@telegram.org, support@telegram.org,sticker@telegram.org, stopCA@telegram.org, recover@telegram.org, DMCA@telegram.org.
16:57:34
Письмо от gera.madara@mail.ru успешно отправлено на Abuse@telegram.org, spam@telegram.org, security@telegram.org, legal@telegram.org, support@telegram.org,sticker@telegram.org, stopCA@telegram.org, recover@telegram.org, DMCA@telegram.org.
16:57:40
Письмо от gera.madara@mail.ru успешно отправлено на Abuse@telegram.org, spam@telegram.org, security@telegram.org, legal@telegram.org, support@telegram.org,sticker@telegram.org, stopCA@telegram.org, recover@telegram.org, DMCA@telegram.org.
16:57:45
Письмо от gera.madara@mail.ru успешно отправлено на Abuse@telegram.org, spam@telegram.org, security@telegram.org, legal@telegram.org, support@telegram.org,sticker@telegram.org, stopCA@telegram.org, recover@telegram.org, DMCA@telegram.org.
16:57:50
Письмо от gera.madara@mail.ru успешно отправлено на Abuse@telegram.org, spam@telegram.org, security@telegram.org, legal@telegram.org, support@telegram.org,sticker@telegram.org, stopCA@telegram.org, recover@telegram.org, DMCA@telegram.org.
16:57:52
Письмо от gera.madara@mail.ru успешно отправлено на Abuse@telegram.org, spam@telegram.org, security@telegram.org, legal@telegram.org, support@telegram.org,sticker@telegram.org, stopCA@telegram.org, recover@telegram.org, DMCA@telegram.org.
16:57:59
Письмо от gera.madara@mail.ru успешно отправлено на Abuse@telegram.org, spam@telegram.org, security@telegram.org, legal@telegram.org, support@telegram.org,sticker@telegram.org, stopCA@telegram.org, recover@telegram.org, DMCA@telegram.org.
16:58:03
Письмо от gera.madara@mail.ru успешно отправлено на Abuse@telegram.org, spam@telegram.org, security@telegram.org, legal@telegram.org, support@telegram.org,sticker@telegram.org, stopCA@telegram.org, recover@telegram.org, DMCA@telegram.org.
16:58:17
Письмо от gera.madara@mail.ru успешно отправлено на Abuse@telegram.org, spam@telegram.org, security@telegram.org, legal@telegram.org, support@telegram.org,sticker@telegram.org, stopCA@telegram.org, recover@telegram.org, DMCA@telegram.org.
16:58:38
Письмо от gera.madara@mail.ru успешно отправлено на Abuse@telegram.org, spam@telegram.org, security@telegram.org, legal@telegram.org, support@telegram.org,sticker@telegram.org, stopCA@telegram.org, recover@telegram.org, DMCA@telegram.org.
16:58:43
Письмо от gera.madara@mail.ru успешно отправлено на Abuse@telegram.org, spam@telegram.org, security@telegram.org, legal@telegram.org, support@telegram.org,sticker@telegram.org, stopCA@telegram.org, recover@telegram.org, DMCA@telegram.org.
Письмо не отправлено по причине: (451, b'Ratelimit exceeded for mailbox gera.madara@mail.ru. Try again later.')
Письмо не отправлено по причине: (451, b'Ratelimit exceeded for mailbox gera.madara@mail.ru. Try again later.')
Письмо не отправлено по причине: (451, b'Ratelimit exceeded for mailbox gera.madara@mail.ru. Try again later.')
Письмо не отправлено по причине: (451, b'Ratelimit exceeded for mailbox gera.madara@mail.ru. Try again later.')
Письмо не отправлено по причине: (451, b'Ratelimit exceeded for mailbox gera.madara@mail.ru. Try again later.')
Письмо не отправлено по причине: (451, b'Ratelimit exceeded for mailbox gera.madara@mail.ru. Try again later.')
Письмо не отправлено по причине: (451, b'Ratelimit exceeded for mailbox gera.madara@mail.ru. Try again later.')
Письмо не отправлено по причине: (451, b'Ratelimit exceeded for mailbox gera.madara@mail.ru. Try again later.')
Письмо не отправлено по причине: (451, b'Ratelimit exceeded for mailbox gera.madara@mail.ru. Try again later.')
Письмо не отправлено по причине: (451, b'Ratelimit exceeded for mailbox gera.madara@mail.ru. Try again later.')
Письмо не отправлено по причине: (451, b'Ratelimit exceeded for mailbox gera.madara@mail.ru. Try again later.')
Письмо не отправлено по причине: (451, b'Ratelimit exceeded for mailbox gera.madara@mail.ru. Try again later.')
Письмо не отправлено по причине: (451, b'Ratelimit exceeded for mailbox gera.madara@mail.ru. Try again later.')
Письмо не отправлено по причине: (451, b'Ratelimit exceeded for mailbox gera.madara@mail.ru. Try again later.')
Письмо не отправлено по причине: (451, b'Ratelimit exceeded for mailbox gera.madara@mail.ru. Try again later.')
Письмо не отправлено по причине: (451, b'Ratelimit exceeded for mailbox gera.madara@mail.ru. Try again later.')
Письмо не отправлено по причине: (451, b'Ratelimit exceeded for mailbox gera.madara@mail.ru. Try again later.')
Письмо не отправлено по причине: (451, b'Ratelimit exceeded for mailbox gera.madara@mail.ru. Try again later.')
Письмо не отправлено по причине: (451, b'Ratelimit exceeded for mailbox gera.madara@mail.ru. Try again later.')
Письмо не отправлено по причине: (451, b'Ratelimit exceeded for mailbox gera.madara@mail.ru. Try again later.')
Письмо не отправлено по причине: (451, b'Ratelimit exceeded for mailbox gera.madara@mail.ru. Try again later.')
Письмо не отправлено по причине: (451, b'Ratelimit exceeded for mailbox gera.madara@mail.ru. Try again later.')
Письмо не отправлено по причине: (451, b'Ratelimit exceeded for mailbox gera.madara@mail.ru. Try again later.')
Письмо не отправлено по причине: (451, b'Ratelimit exceeded for mailbox gera.madara@mail.ru. Try again later.')
Письмо не отправлено по причине: (451, b'Ratelimit exceeded for mailbox gera.madara@mail.ru. Try again later.')
Письмо не отправлено по причине: (451, b'Ratelimit exceeded for mailbox gera.madara@mail.ru. Try again later.')
Письмо не отправлено по причине: (451, b'Ratelimit exceeded for mailbox gera.madara@mail.ru. Try again later.')
Письмо не отправлено по причине: (451, b'Ratelimit exceeded for mailbox gera.madara@mail.ru. Try again later.')
Письмо не отправлено по причине: (451, b'Ratelimit exceeded for mailbox gera.madara@mail.ru. Try again later.')
Письмо не отправлено по причине: (451, b'Ratelimit exceeded for mailbox gera.madara@mail.ru. Try again later.')
Письмо не отправлено по причине: (451, b'Ratelimit exceeded for mailbox gera.madara@mail.ru. Try again later.')
Письмо не отправлено по причине: (451, b'Ratelimit exceeded for mailbox gera.madara@mail.ru. Try again later.')
Письмо не отправлено по причине: (451, b'Ratelimit exceeded for mailbox gera.madara@mail.ru. Try again later.')
Письмо не отправлено по причине: (451, b'Ratelimit exceeded for mailbox gera.madara@mail.ru. Try again later.')
Письмо не отправлено по причине: (451, b'Ratelimit exceeded for mailbox gera.madara@mail.ru. Try again later.')
Письмо не отправлено по причине: (451, b'Ratelimit exceeded for mailbox gera.madara@mail.ru. Try again later.')
Письмо не отправлено по причине: (451, b'Ratelimit exceeded for mailbox gera.madara@mail.ru. Try again later.')
2024-11-02 23:28:38,048 (__init__.py:1241 MainThread) ERROR - TeleBot: "Threaded polling exception: A request to the Telegram API was unsuccessful. Error code: 502. Description: Bad Gateway"
2024-11-02 23:28:38,049 (__init__.py:1243 MainThread) ERROR - TeleBot: "Exception traceback:
Traceback (most recent call last):
  File "/root/snb/venv/lib/python3.12/site-packages/telebot/__init__.py", line 1234, in __threaded_polling
    polling_thread.raise_exceptions()
  File "/root/snb/venv/lib/python3.12/site-packages/telebot/util.py", line 111, in raise_exceptions
    raise self.exception_info
  File "/root/snb/venv/lib/python3.12/site-packages/telebot/util.py", line 93, in run
    task(*args, **kwargs)
  File "/root/snb/venv/lib/python3.12/site-packages/telebot/__init__.py", line 688, in __retrieve_updates
    updates = self.get_updates(offset=(self.last_update_id + 1),
             ^^^^^^^^^^^^^^^^^^^^^^^^^^^^^^^^^^^^^^^^^^^^^^^^^^
  File "/root/snb/venv/lib/python3.12/site-packages/telebot/__init__.py", line 660, in get_updates
    json_updates = apihelper.get_updates(
                   ^^^^^^^^^^^^^^^^^^^^^^
  File "/root/snb/venv/lib/python3.12/site-packages/telebot/apihelper.py", line 330, in get_updates
    return _make_request(token, method_url, params=payload)
           ^^^^^^^^^^^^^^^^^^^^^^^^^^^^^^^^^^^^^^^^^^^^^^^^
  File "/root/snb/venv/lib/python3.12/site-packages/telebot/apihelper.py", line 168, in _make_request
    json_result = _check_result(method_name, result)
                  ^^^^^^^^^^^^^^^^^^^^^^^^^^^^^^^^^^
  File "/root/snb/venv/lib/python3.12/site-packages/telebot/apihelper.py", line 195, in _check_result
    raise ApiTelegramException(method_name, result, result_json)
telebot.apihelper.ApiTelegramException: A request to the Telegram API was unsuccessful. Error code: 502. Description: Bad Gateway
"
2024-11-02 23:28:38,314 (__init__.py:1241 MainThread) ERROR - TeleBot: "Threaded polling exception: A request to the Telegram API was unsuccessful. Error code: 502. Description: Bad Gateway"
2024-11-02 23:28:38,314 (__init__.py:1243 MainThread) ERROR - TeleBot: "Exception traceback:
Traceback (most recent call last):
  File "/root/snb/venv/lib/python3.12/site-packages/telebot/__init__.py", line 1234, in __threaded_polling
    polling_thread.raise_exceptions()
  File "/root/snb/venv/lib/python3.12/site-packages/telebot/util.py", line 111, in raise_exceptions
    raise self.exception_info
  File "/root/snb/venv/lib/python3.12/site-packages/telebot/util.py", line 93, in run
    task(*args, **kwargs)
  File "/root/snb/venv/lib/python3.12/site-packages/telebot/__init__.py", line 688, in __retrieve_updates
    updates = self.get_updates(offset=(self.last_update_id + 1),
             ^^^^^^^^^^^^^^^^^^^^^^^^^^^^^^^^^^^^^^^^^^^^^^^^^^
  File "/root/snb/venv/lib/python3.12/site-packages/telebot/__init__.py", line 660, in get_updates
    json_updates = apihelper.get_updates(
                   ^^^^^^^^^^^^^^^^^^^^^^
  File "/root/snb/venv/lib/python3.12/site-packages/telebot/apihelper.py", line 330, in get_updates
    return _make_request(token, method_url, params=payload)
           ^^^^^^^^^^^^^^^^^^^^^^^^^^^^^^^^^^^^^^^^^^^^^^^^
  File "/root/snb/venv/lib/python3.12/site-packages/telebot/apihelper.py", line 168, in _make_request
    json_result = _check_result(method_name, result)
                  ^^^^^^^^^^^^^^^^^^^^^^^^^^^^^^^^^^
  File "/root/snb/venv/lib/python3.12/site-packages/telebot/apihelper.py", line 195, in _check_result
    raise ApiTelegramException(method_name, result, result_json)
telebot.apihelper.ApiTelegramException: A request to the Telegram API was unsuccessful. Error code: 502. Description: Bad Gateway
"
2024-11-02 23:28:38,829 (__init__.py:1241 MainThread) ERROR - TeleBot: "Threaded polling exception: A request to the Telegram API was unsuccessful. Error code: 502. Description: Bad Gateway"
2024-11-02 23:28:38,830 (__init__.py:1243 MainThread) ERROR - TeleBot: "Exception traceback:
Traceback (most recent call last):
  File "/root/snb/venv/lib/python3.12/site-packages/telebot/__init__.py", line 1234, in __threaded_polling
    polling_thread.raise_exceptions()
  File "/root/snb/venv/lib/python3.12/site-packages/telebot/util.py", line 111, in raise_exceptions
    raise self.exception_info
  File "/root/snb/venv/lib/python3.12/site-packages/telebot/util.py", line 93, in run
    task(*args, **kwargs)
  File "/root/snb/venv/lib/python3.12/site-packages/telebot/__init__.py", line 688, in __retrieve_updates
    updates = self.get_updates(offset=(self.last_update_id + 1),
             ^^^^^^^^^^^^^^^^^^^^^^^^^^^^^^^^^^^^^^^^^^^^^^^^^^
  File "/root/snb/venv/lib/python3.12/site-packages/telebot/__init__.py", line 660, in get_updates
    json_updates = apihelper.get_updates(
                   ^^^^^^^^^^^^^^^^^^^^^^
  File "/root/snb/venv/lib/python3.12/site-packages/telebot/apihelper.py", line 330, in get_updates
    return _make_request(token, method_url, params=payload)
           ^^^^^^^^^^^^^^^^^^^^^^^^^^^^^^^^^^^^^^^^^^^^^^^^
  File "/root/snb/venv/lib/python3.12/site-packages/telebot/apihelper.py", line 168, in _make_request
    json_result = _check_result(method_name, result)
                  ^^^^^^^^^^^^^^^^^^^^^^^^^^^^^^^^^^
  File "/root/snb/venv/lib/python3.12/site-packages/telebot/apihelper.py", line 195, in _check_result
    raise ApiTelegramException(method_name, result, result_json)
telebot.apihelper.ApiTelegramException: A request to the Telegram API was unsuccessful. Error code: 502. Description: Bad Gateway
"
2024-11-02 23:28:39,846 (__init__.py:1241 MainThread) ERROR - TeleBot: "Threaded polling exception: A request to the Telegram API was unsuccessful. Error code: 502. Description: Bad Gateway"
2024-11-02 23:28:39,847 (__init__.py:1243 MainThread) ERROR - TeleBot: "Exception traceback:
Traceback (most recent call last):
  File "/root/snb/venv/lib/python3.12/site-packages/telebot/__init__.py", line 1234, in __threaded_polling
    polling_thread.raise_exceptions()
  File "/root/snb/venv/lib/python3.12/site-packages/telebot/util.py", line 111, in raise_exceptions
    raise self.exception_info
  File "/root/snb/venv/lib/python3.12/site-packages/telebot/util.py", line 93, in run
    task(*args, **kwargs)
  File "/root/snb/venv/lib/python3.12/site-packages/telebot/__init__.py", line 688, in __retrieve_updates
    updates = self.get_updates(offset=(self.last_update_id + 1),
             ^^^^^^^^^^^^^^^^^^^^^^^^^^^^^^^^^^^^^^^^^^^^^^^^^^
  File "/root/snb/venv/lib/python3.12/site-packages/telebot/__init__.py", line 660, in get_updates
    json_updates = apihelper.get_updates(
                   ^^^^^^^^^^^^^^^^^^^^^^
  File "/root/snb/venv/lib/python3.12/site-packages/telebot/apihelper.py", line 330, in get_updates
    return _make_request(token, method_url, params=payload)
           ^^^^^^^^^^^^^^^^^^^^^^^^^^^^^^^^^^^^^^^^^^^^^^^^
  File "/root/snb/venv/lib/python3.12/site-packages/telebot/apihelper.py", line 168, in _make_request
    json_result = _check_result(method_name, result)
                  ^^^^^^^^^^^^^^^^^^^^^^^^^^^^^^^^^^
  File "/root/snb/venv/lib/python3.12/site-packages/telebot/apihelper.py", line 195, in _check_result
    raise ApiTelegramException(method_name, result, result_json)
telebot.apihelper.ApiTelegramException: A request to the Telegram API was unsuccessful. Error code: 502. Description: Bad Gateway
"
2024-11-02 23:28:41,862 (__init__.py:1241 MainThread) ERROR - TeleBot: "Threaded polling exception: A request to the Telegram API was unsuccessful. Error code: 502. Description: Bad Gateway"
2024-11-02 23:28:41,863 (__init__.py:1243 MainThread) ERROR - TeleBot: "Exception traceback:
Traceback (most recent call last):
  File "/root/snb/venv/lib/python3.12/site-packages/telebot/__init__.py", line 1234, in __threaded_polling
    polling_thread.raise_exceptions()
  File "/root/snb/venv/lib/python3.12/site-packages/telebot/util.py", line 111, in raise_exceptions
    raise self.exception_info
  File "/root/snb/venv/lib/python3.12/site-packages/telebot/util.py", line 93, in run
    task(*args, **kwargs)
  File "/root/snb/venv/lib/python3.12/site-packages/telebot/__init__.py", line 688, in __retrieve_updates
    updates = self.get_updates(offset=(self.last_update_id + 1),
             ^^^^^^^^^^^^^^^^^^^^^^^^^^^^^^^^^^^^^^^^^^^^^^^^^^
  File "/root/snb/venv/lib/python3.12/site-packages/telebot/__init__.py", line 660, in get_updates
    json_updates = apihelper.get_updates(
                   ^^^^^^^^^^^^^^^^^^^^^^
  File "/root/snb/venv/lib/python3.12/site-packages/telebot/apihelper.py", line 330, in get_updates
    return _make_request(token, method_url, params=payload)
           ^^^^^^^^^^^^^^^^^^^^^^^^^^^^^^^^^^^^^^^^^^^^^^^^
  File "/root/snb/venv/lib/python3.12/site-packages/telebot/apihelper.py", line 168, in _make_request
    json_result = _check_result(method_name, result)
                  ^^^^^^^^^^^^^^^^^^^^^^^^^^^^^^^^^^
  File "/root/snb/venv/lib/python3.12/site-packages/telebot/apihelper.py", line 195, in _check_result
    raise ApiTelegramException(method_name, result, result_json)
telebot.apihelper.ApiTelegramException: A request to the Telegram API was unsuccessful. Error code: 502. Description: Bad Gateway
"
Письмо не отправлено по причине: (451, b'Ratelimit exceeded for mailbox gera.madara@mail.ru. Try again later.')
Письмо не отправлено по причине: (451, b'Ratelimit exceeded for mailbox gera.madara@mail.ru. Try again later.')
Письмо не отправлено по причине: (451, b'Ratelimit exceeded for mailbox gera.madara@mail.ru. Try again later.')
Письмо не отправлено по причине: (451, b'Ratelimit exceeded for mailbox gera.madara@mail.ru. Try again later.')
Письмо не отправлено по причине: (451, b'Ratelimit exceeded for mailbox gera.madara@mail.ru. Try again later.')
Письмо не отправлено по причине: (451, b'Ratelimit exceeded for mailbox gera.madara@mail.ru. Try again later.')
Письмо не отправлено по причине: (451, b'Ratelimit exceeded for mailbox gera.madara@mail.ru. Try again later.')
Письмо не отправлено по причине: (451, b'Ratelimit exceeded for mailbox gera.madara@mail.ru. Try again later.')
Письмо не отправлено по причине: (451, b'Ratelimit exceeded for mailbox gera.madara@mail.ru. Try again later.')
Письмо не отправлено по причине: (451, b'Ratelimit exceeded for mailbox gera.madara@mail.ru. Try again later.')
Письмо не отправлено по причине: (451, b'Ratelimit exceeded for mailbox gera.madara@mail.ru. Try again later.')
Письмо не отправлено по причине: (451, b'Ratelimit exceeded for mailbox gera.madara@mail.ru. Try again later.')
Traceback (most recent call last):
  File "/root/snb/venv/lib/python3.12/site-packages/urllib3/connectionpool.py", line 536, in _make_request
    response = conn.getresponse()
               ^^^^^^^^^^^^^^^^^^
  File "/root/snb/venv/lib/python3.12/site-packages/urllib3/connection.py", line 507, in getresponse
    httplib_response = super().getresponse()
                       ^^^^^^^^^^^^^^^^^^^^^
  File "/usr/lib/python3.12/http/client.py", line 1428, in getresponse
    response.begin()
  File "/usr/lib/python3.12/http/client.py", line 331, in begin
    version, status, reason = self._read_status()
                              ^^^^^^^^^^^^^^^^^^^
  File "/usr/lib/python3.12/http/client.py", line 292, in _read_status
    line = str(self.fp.readline(_MAXLINE + 1), "iso-8859-1")
               ^^^^^^^^^^^^^^^^^^^^^^^^^^^^^^
  File "/usr/lib/python3.12/socket.py", line 707, in readinto
    return self._sock.recv_into(b)
           ^^^^^^^^^^^^^^^^^^^^^^^
  File "/usr/lib/python3.12/ssl.py", line 1252, in recv_into
    return self.read(nbytes, buffer)
           ^^^^^^^^^^^^^^^^^^^^^^^^^
  File "/usr/lib/python3.12/ssl.py", line 1104, in read
    return self._sslobj.read(len, buffer)
           ^^^^^^^^^^^^^^^^^^^^^^^^^^^^^^
TimeoutError: The read operation timed out

The above exception was the direct cause of the following exception:

Traceback (most recent call last):
  File "/root/snb/venv/lib/python3.12/site-packages/requests/adapters.py", line 667, in send
    resp = conn.urlopen(
           ^^^^^^^^^^^^^
  File "/root/snb/venv/lib/python3.12/site-packages/urllib3/connectionpool.py", line 843, in urlopen
    retries = retries.increment(
              ^^^^^^^^^^^^^^^^^^
  File "/root/snb/venv/lib/python3.12/site-packages/urllib3/util/retry.py", line 474, in increment
    raise reraise(type(error), error, _stacktrace)
          ^^^^^^^^^^^^^^^^^^^^^^^^^^^^^^^^^^^^^^^^
  File "/root/snb/venv/lib/python3.12/site-packages/urllib3/util/util.py", line 39, in reraise
    raise value
  File "/root/snb/venv/lib/python3.12/site-packages/urllib3/connectionpool.py", line 789, in urlopen
    response = self._make_request(
               ^^^^^^^^^^^^^^^^^^^
  File "/root/snb/venv/lib/python3.12/site-packages/urllib3/connectionpool.py", line 538, in _make_request
    self._raise_timeout(err=e, url=url, timeout_value=read_timeout)
  File "/root/snb/venv/lib/python3.12/site-packages/urllib3/connectionpool.py", line 369, in _raise_timeout
    raise ReadTimeoutError(
urllib3.exceptions.ReadTimeoutError: HTTPSConnectionPool(host='api.telegram.org', port=443): Read timed out. (read timeout=25)

During handling of the above exception, another exception occurred:

Traceback (most recent call last):
  File "/root/snb/main.py", line 502, in <module>
    bot.polling(none_stop=True)
  File "/root/snb/venv/lib/python3.12/site-packages/telebot/__init__.py", line 1198, in polling
    self.__threaded_polling(non_stop=non_stop, interval=interval, timeout=timeout, long_polling_timeout=long_polling_timeout,
  File "/root/snb/venv/lib/python3.12/site-packages/telebot/__init__.py", line 1273, in __threaded_polling
    raise e
  File "/root/snb/venv/lib/python3.12/site-packages/telebot/__init__.py", line 1234, in __threaded_polling
    polling_thread.raise_exceptions()
  File "/root/snb/venv/lib/python3.12/site-packages/telebot/util.py", line 111, in raise_exceptions
    raise self.exception_info
  File "/root/snb/venv/lib/python3.12/site-packages/telebot/util.py", line 93, in run
    task(*args, **kwargs)
  File "/root/snb/venv/lib/python3.12/site-packages/telebot/__init__.py", line 688, in __retrieve_updates
    updates = self.get_updates(offset=(self.last_update_id + 1), 
              ^^^^^^^^^^^^^^^^^^^^^^^^^^^^^^^^^^^^^^^^^^^^^^^^^^
  File "/root/snb/venv/lib/python3.12/site-packages/telebot/__init__.py", line 660, in get_updates
    json_updates = apihelper.get_updates(
                   ^^^^^^^^^^^^^^^^^^^^^^
  File "/root/snb/venv/lib/python3.12/site-packages/telebot/apihelper.py", line 330, in get_updates
    return _make_request(token, method_url, params=payload)
           ^^^^^^^^^^^^^^^^^^^^^^^^^^^^^^^^^^^^^^^^^^^^^^^^
  File "/root/snb/venv/lib/python3.12/site-packages/telebot/apihelper.py", line 162, in _make_request
    result = _get_req_session().request(
             ^^^^^^^^^^^^^^^^^^^^^^^^^^^
  File "/root/snb/venv/lib/python3.12/site-packages/requests/sessions.py", line 589, in request
    resp = self.send(prep, **send_kwargs)
           ^^^^^^^^^^^^^^^^^^^^^^^^^^^^^^
  File "/root/snb/venv/lib/python3.12/site-packages/requests/sessions.py", line 703, in send
    r = adapter.send(request, **kwargs)
        ^^^^^^^^^^^^^^^^^^^^^^^^^^^^^^^
  File "/root/snb/venv/lib/python3.12/site-packages/requests/adapters.py", line 713, in send
    raise ReadTimeout(e, request=request)
requests.exceptions.ReadTimeout: HTTPSConnectionPool(host='api.telegram.org', port=443): Read timed out. (read timeout=25)
Traceback (most recent call last):
  File "/root/snb/main.py", line 1, in <module>
    import telebot
ModuleNotFoundError: No module named 'telebot'
08:09:01
Письмо от gera.madara@mail.ru успешно отправлено на Abuse@telegram.org, spam@telegram.org, security@telegram.org, legal@telegram.org, support@telegram.org,sticker@telegram.org, stopCA@telegram.org, recover@telegram.org, DMCA@telegram.org.
08:09:03
Письмо от gera.madara@mail.ru успешно отправлено на Abuse@telegram.org, spam@telegram.org, security@telegram.org, legal@telegram.org, support@telegram.org,sticker@telegram.org, stopCA@telegram.org, recover@telegram.org, DMCA@telegram.org.
08:09:05
Письмо от gera.madara@mail.ru успешно отправлено на Abuse@telegram.org, spam@telegram.org, security@telegram.org, legal@telegram.org, support@telegram.org,sticker@telegram.org, stopCA@telegram.org, recover@telegram.org, DMCA@telegram.org.
08:09:07
Письмо от gera.madara@mail.ru успешно отправлено на Abuse@telegram.org, spam@telegram.org, security@telegram.org, legal@telegram.org, support@telegram.org,sticker@telegram.org, stopCA@telegram.org, recover@telegram.org, DMCA@telegram.org.
08:09:09
Письмо от gera.madara@mail.ru успешно отправлено на Abuse@telegram.org, spam@telegram.org, security@telegram.org, legal@telegram.org, support@telegram.org,sticker@telegram.org, stopCA@telegram.org, recover@telegram.org, DMCA@telegram.org.
08:09:10
Письмо от gera.madara@mail.ru успешно отправлено на Abuse@telegram.org, spam@telegram.org, security@telegram.org, legal@telegram.org, support@telegram.org,sticker@telegram.org, stopCA@telegram.org, recover@telegram.org, DMCA@telegram.org.
08:09:12
Письмо от gera.madara@mail.ru успешно отправлено на Abuse@telegram.org, spam@telegram.org, security@telegram.org, legal@telegram.org, support@telegram.org,sticker@telegram.org, stopCA@telegram.org, recover@telegram.org, DMCA@telegram.org.
08:09:14
Письмо от gera.madara@mail.ru успешно отправлено на Abuse@telegram.org, spam@telegram.org, security@telegram.org, legal@telegram.org, support@telegram.org,sticker@telegram.org, stopCA@telegram.org, recover@telegram.org, DMCA@telegram.org.
08:09:16
Письмо от gera.madara@mail.ru успешно отправлено на Abuse@telegram.org, spam@telegram.org, security@telegram.org, legal@telegram.org, support@telegram.org,sticker@telegram.org, stopCA@telegram.org, recover@telegram.org, DMCA@telegram.org.
08:09:18
Письмо от gera.madara@mail.ru успешно отправлено на Abuse@telegram.org, spam@telegram.org, security@telegram.org, legal@telegram.org, support@telegram.org,sticker@telegram.org, stopCA@telegram.org, recover@telegram.org, DMCA@telegram.org.
08:09:20
Письмо от gera.madara@mail.ru успешно отправлено на Abuse@telegram.org, spam@telegram.org, security@telegram.org, legal@telegram.org, support@telegram.org,sticker@telegram.org, stopCA@telegram.org, recover@telegram.org, DMCA@telegram.org.
08:09:22
Письмо от gera.madara@mail.ru успешно отправлено на Abuse@telegram.org, spam@telegram.org, security@telegram.org, legal@telegram.org, support@telegram.org,sticker@telegram.org, stopCA@telegram.org, recover@telegram.org, DMCA@telegram.org.
09:40:46
Письмо от gera.madara@mail.ru успешно отправлено на Abuse@telegram.org, spam@telegram.org, security@telegram.org, legal@telegram.org, support@telegram.org,sticker@telegram.org, stopCA@telegram.org, recover@telegram.org, DMCA@telegram.org.
09:40:49
Письмо от gera.madara@mail.ru успешно отправлено на Abuse@telegram.org, spam@telegram.org, security@telegram.org, legal@telegram.org, support@telegram.org,sticker@telegram.org, stopCA@telegram.org, recover@telegram.org, DMCA@telegram.org.
09:40:51
Письмо от gera.madara@mail.ru успешно отправлено на Abuse@telegram.org, spam@telegram.org, security@telegram.org, legal@telegram.org, support@telegram.org,sticker@telegram.org, stopCA@telegram.org, recover@telegram.org, DMCA@telegram.org.
09:40:53
Письмо от gera.madara@mail.ru успешно отправлено на Abuse@telegram.org, spam@telegram.org, security@telegram.org, legal@telegram.org, support@telegram.org,sticker@telegram.org, stopCA@telegram.org, recover@telegram.org, DMCA@telegram.org.
09:40:55
Письмо от gera.madara@mail.ru успешно отправлено на Abuse@telegram.org, spam@telegram.org, security@telegram.org, legal@telegram.org, support@telegram.org,sticker@telegram.org, stopCA@telegram.org, recover@telegram.org, DMCA@telegram.org.
09:40:57
Письмо от gera.madara@mail.ru успешно отправлено на Abuse@telegram.org, spam@telegram.org, security@telegram.org, legal@telegram.org, support@telegram.org,sticker@telegram.org, stopCA@telegram.org, recover@telegram.org, DMCA@telegram.org.
09:40:59
Письмо от gera.madara@mail.ru успешно отправлено на Abuse@telegram.org, spam@telegram.org, security@telegram.org, legal@telegram.org, support@telegram.org,sticker@telegram.org, stopCA@telegram.org, recover@telegram.org, DMCA@telegram.org.
09:41:01
Письмо от gera.madara@mail.ru успешно отправлено на Abuse@telegram.org, spam@telegram.org, security@telegram.org, legal@telegram.org, support@telegram.org,sticker@telegram.org, stopCA@telegram.org, recover@telegram.org, DMCA@telegram.org.
09:41:03
Письмо от gera.madara@mail.ru успешно отправлено на Abuse@telegram.org, spam@telegram.org, security@telegram.org, legal@telegram.org, support@telegram.org,sticker@telegram.org, stopCA@telegram.org, recover@telegram.org, DMCA@telegram.org.
09:41:05
Письмо от gera.madara@mail.ru успешно отправлено на Abuse@telegram.org, spam@telegram.org, security@telegram.org, legal@telegram.org, support@telegram.org,sticker@telegram.org, stopCA@telegram.org, recover@telegram.org, DMCA@telegram.org.
09:41:06
Письмо от gera.madara@mail.ru успешно отправлено на Abuse@telegram.org, spam@telegram.org, security@telegram.org, legal@telegram.org, support@telegram.org,sticker@telegram.org, stopCA@telegram.org, recover@telegram.org, DMCA@telegram.org.
09:41:08
Письмо от gera.madara@mail.ru успешно отправлено на Abuse@telegram.org, spam@telegram.org, security@telegram.org, legal@telegram.org, support@telegram.org,sticker@telegram.org, stopCA@telegram.org, recover@telegram.org, DMCA@telegram.org.
Письмо не отправлено по причине: (451, b'Ratelimit exceeded for mailbox gera.madara@mail.ru. Try again later.')
Письмо не отправлено по причине: (451, b'Ratelimit exceeded for mailbox gera.madara@mail.ru. Try again later.')
Письмо не отправлено по причине: (451, b'Ratelimit exceeded for mailbox gera.madara@mail.ru. Try again later.')
Письмо не отправлено по причине: (451, b'Ratelimit exceeded for mailbox gera.madara@mail.ru. Try again later.')
Письмо не отправлено по причине: (451, b'Ratelimit exceeded for mailbox gera.madara@mail.ru. Try again later.')
Письмо не отправлено по причине: (451, b'Ratelimit exceeded for mailbox gera.madara@mail.ru. Try again later.')
Письмо не отправлено по причине: (451, b'Ratelimit exceeded for mailbox gera.madara@mail.ru. Try again later.')
Письмо не отправлено по причине: (451, b'Ratelimit exceeded for mailbox gera.madara@mail.ru. Try again later.')
Письмо не отправлено по причине: (451, b'Ratelimit exceeded for mailbox gera.madara@mail.ru. Try again later.')
Письмо не отправлено по причине: (451, b'Ratelimit exceeded for mailbox gera.madara@mail.ru. Try again later.')
Письмо не отправлено по причине: (451, b'Ratelimit exceeded for mailbox gera.madara@mail.ru. Try again later.')
Письмо не отправлено по причине: (451, b'Ratelimit exceeded for mailbox gera.madara@mail.ru. Try again later.')
Письмо не отправлено по причине: (451, b'Ratelimit exceeded for mailbox gera.madara@mail.ru. Try again later.')
Письмо не отправлено по причине: (451, b'Ratelimit exceeded for mailbox gera.madara@mail.ru. Try again later.')
Письмо не отправлено по причине: (451, b'Ratelimit exceeded for mailbox gera.madara@mail.ru. Try again later.')
Письмо не отправлено по причине: (451, b'Ratelimit exceeded for mailbox gera.madara@mail.ru. Try again later.')
Письмо не отправлено по причине: (451, b'Ratelimit exceeded for mailbox gera.madara@mail.ru. Try again later.')
Письмо не отправлено по причине: (451, b'Ratelimit exceeded for mailbox gera.madara@mail.ru. Try again later.')
Письмо не отправлено по причине: (451, b'Ratelimit exceeded for mailbox gera.madara@mail.ru. Try again later.')
Письмо не отправлено по причине: (451, b'Ratelimit exceeded for mailbox gera.madara@mail.ru. Try again later.')
Письмо не отправлено по причине: (451, b'Ratelimit exceeded for mailbox gera.madara@mail.ru. Try again later.')
Письмо не отправлено по причине: (451, b'Ratelimit exceeded for mailbox gera.madara@mail.ru. Try again later.')
Письмо не отправлено по причине: (451, b'Ratelimit exceeded for mailbox gera.madara@mail.ru. Try again later.')
Письмо не отправлено по причине: (451, b'Ratelimit exceeded for mailbox gera.madara@mail.ru. Try again later.')
16:29:09
Письмо от gera.madara@mail.ru успешно отправлено на Abuse@telegram.org, spam@telegram.org, security@telegram.org, legal@telegram.org, support@telegram.org,sticker@telegram.org, stopCA@telegram.org, recover@telegram.org, DMCA@telegram.org.
16:29:11
Письмо от gera.madara@mail.ru успешно отправлено на Abuse@telegram.org, spam@telegram.org, security@telegram.org, legal@telegram.org, support@telegram.org,sticker@telegram.org, stopCA@telegram.org, recover@telegram.org, DMCA@telegram.org.
16:29:13
Письмо от gera.madara@mail.ru успешно отправлено на Abuse@telegram.org, spam@telegram.org, security@telegram.org, legal@telegram.org, support@telegram.org,sticker@telegram.org, stopCA@telegram.org, recover@telegram.org, DMCA@telegram.org.
16:29:15
Письмо от gera.madara@mail.ru успешно отправлено на Abuse@telegram.org, spam@telegram.org, security@telegram.org, legal@telegram.org, support@telegram.org,sticker@telegram.org, stopCA@telegram.org, recover@telegram.org, DMCA@telegram.org.
16:29:18
Письмо от gera.madara@mail.ru успешно отправлено на Abuse@telegram.org, spam@telegram.org, security@telegram.org, legal@telegram.org, support@telegram.org,sticker@telegram.org, stopCA@telegram.org, recover@telegram.org, DMCA@telegram.org.
16:29:20
Письмо от gera.madara@mail.ru успешно отправлено на Abuse@telegram.org, spam@telegram.org, security@telegram.org, legal@telegram.org, support@telegram.org,sticker@telegram.org, stopCA@telegram.org, recover@telegram.org, DMCA@telegram.org.
16:29:24
Письмо от gera.madara@mail.ru успешно отправлено на Abuse@telegram.org, spam@telegram.org, security@telegram.org, legal@telegram.org, support@telegram.org,sticker@telegram.org, stopCA@telegram.org, recover@telegram.org, DMCA@telegram.org.
16:29:26
Письмо от gera.madara@mail.ru успешно отправлено на Abuse@telegram.org, spam@telegram.org, security@telegram.org, legal@telegram.org, support@telegram.org,sticker@telegram.org, stopCA@telegram.org, recover@telegram.org, DMCA@telegram.org.
16:29:28
Письмо от gera.madara@mail.ru успешно отправлено на Abuse@telegram.org, spam@telegram.org, security@telegram.org, legal@telegram.org, support@telegram.org,sticker@telegram.org, stopCA@telegram.org, recover@telegram.org, DMCA@telegram.org.
16:29:30
Письмо от gera.madara@mail.ru успешно отправлено на Abuse@telegram.org, spam@telegram.org, security@telegram.org, legal@telegram.org, support@telegram.org,sticker@telegram.org, stopCA@telegram.org, recover@telegram.org, DMCA@telegram.org.
16:29:32
Письмо от gera.madara@mail.ru успешно отправлено на Abuse@telegram.org, spam@telegram.org, security@telegram.org, legal@telegram.org, support@telegram.org,sticker@telegram.org, stopCA@telegram.org, recover@telegram.org, DMCA@telegram.org.
16:29:34
Письмо от gera.madara@mail.ru успешно отправлено на Abuse@telegram.org, spam@telegram.org, security@telegram.org, legal@telegram.org, support@telegram.org,sticker@telegram.org, stopCA@telegram.org, recover@telegram.org, DMCA@telegram.org.
Письмо не отправлено по причине: (451, b'Ratelimit exceeded for mailbox gera.madara@mail.ru. Try again later.')
Письмо не отправлено по причине: (451, b'Ratelimit exceeded for mailbox gera.madara@mail.ru. Try again later.')
Письмо не отправлено по причине: (451, b'Ratelimit exceeded for mailbox gera.madara@mail.ru. Try again later.')
Письмо не отправлено по причине: (451, b'Ratelimit exceeded for mailbox gera.madara@mail.ru. Try again later.')
Письмо не отправлено по причине: (451, b'Ratelimit exceeded for mailbox gera.madara@mail.ru. Try again later.')
Письмо не отправлено по причине: (451, b'Ratelimit exceeded for mailbox gera.madara@mail.ru. Try again later.')
Письмо не отправлено по причине: (451, b'Ratelimit exceeded for mailbox gera.madara@mail.ru. Try again later.')
Письмо не отправлено по причине: (451, b'Ratelimit exceeded for mailbox gera.madara@mail.ru. Try again later.')
Письмо не отправлено по причине: (451, b'Ratelimit exceeded for mailbox gera.madara@mail.ru. Try again later.')
Письмо не отправлено по причине: (451, b'Ratelimit exceeded for mailbox gera.madara@mail.ru. Try again later.')
Письмо не отправлено по причине: (451, b'Ratelimit exceeded for mailbox gera.madara@mail.ru. Try again later.')
Письмо не отправлено по причине: (451, b'Ratelimit exceeded for mailbox gera.madara@mail.ru. Try again later.')
Письмо не отправлено по причине: (451, b'Ratelimit exceeded for mailbox gera.madara@mail.ru. Try again later.')
Письмо не отправлено по причине: (451, b'Ratelimit exceeded for mailbox gera.madara@mail.ru. Try again later.')
Письмо не отправлено по причине: (451, b'Ratelimit exceeded for mailbox gera.madara@mail.ru. Try again later.')
Письмо не отправлено по причине: (451, b'Ratelimit exceeded for mailbox gera.madara@mail.ru. Try again later.')
Письмо не отправлено по причине: (451, b'Ratelimit exceeded for mailbox gera.madara@mail.ru. Try again later.')
Письмо не отправлено по причине: (451, b'Ratelimit exceeded for mailbox gera.madara@mail.ru. Try again later.')
Письмо не отправлено по причине: (451, b'Ratelimit exceeded for mailbox gera.madara@mail.ru. Try again later.')
Письмо не отправлено по причине: (451, b'Ratelimit exceeded for mailbox gera.madara@mail.ru. Try again later.')
Письмо не отправлено по причине: (451, b'Ratelimit exceeded for mailbox gera.madara@mail.ru. Try again later.')
Письмо не отправлено по причине: (451, b'Ratelimit exceeded for mailbox gera.madara@mail.ru. Try again later.')
2024-11-05 01:11:22,321 (__init__.py:1241 MainThread) ERROR - TeleBot: "Threaded polling exception: A request to the Telegram API was unsuccessful. Error code: 502. Description: Bad Gateway"
2024-11-05 01:11:22,322 (__init__.py:1243 MainThread) ERROR - TeleBot: "Exception traceback:
Traceback (most recent call last):
  File "/root/venv/lib/python3.12/site-packages/telebot/__init__.py", line 1234, in __threaded_polling
    polling_thread.raise_exceptions()
  File "/root/venv/lib/python3.12/site-packages/telebot/util.py", line 111, in raise_exceptions
    raise self.exception_info
  File "/root/venv/lib/python3.12/site-packages/telebot/util.py", line 93, in run
    task(*args, **kwargs)
  File "/root/venv/lib/python3.12/site-packages/telebot/__init__.py", line 688, in __retrieve_updates
    updates = self.get_updates(offset=(self.last_update_id + 1),
             ^^^^^^^^^^^^^^^^^^^^^^^^^^^^^^^^^^^^^^^^^^^^^^^^^^
  File "/root/venv/lib/python3.12/site-packages/telebot/__init__.py", line 660, in get_updates
    json_updates = apihelper.get_updates(
                   ^^^^^^^^^^^^^^^^^^^^^^
  File "/root/venv/lib/python3.12/site-packages/telebot/apihelper.py", line 330, in get_updates
    return _make_request(token, method_url, params=payload)
           ^^^^^^^^^^^^^^^^^^^^^^^^^^^^^^^^^^^^^^^^^^^^^^^^
  File "/root/venv/lib/python3.12/site-packages/telebot/apihelper.py", line 168, in _make_request
    json_result = _check_result(method_name, result)
                  ^^^^^^^^^^^^^^^^^^^^^^^^^^^^^^^^^^
  File "/root/venv/lib/python3.12/site-packages/telebot/apihelper.py", line 195, in _check_result
    raise ApiTelegramException(method_name, result, result_json)
telebot.apihelper.ApiTelegramException: A request to the Telegram API was unsuccessful. Error code: 502. Description: Bad Gateway
"
2024-11-05 01:11:22,602 (__init__.py:1241 MainThread) ERROR - TeleBot: "Threaded polling exception: A request to the Telegram API was unsuccessful. Error code: 502. Description: Bad Gateway"
2024-11-05 01:11:22,612 (__init__.py:1243 MainThread) ERROR - TeleBot: "Exception traceback:
Traceback (most recent call last):
  File "/root/venv/lib/python3.12/site-packages/telebot/__init__.py", line 1234, in __threaded_polling
    polling_thread.raise_exceptions()
  File "/root/venv/lib/python3.12/site-packages/telebot/util.py", line 111, in raise_exceptions
    raise self.exception_info
  File "/root/venv/lib/python3.12/site-packages/telebot/util.py", line 93, in run
    task(*args, **kwargs)
  File "/root/venv/lib/python3.12/site-packages/telebot/__init__.py", line 688, in __retrieve_updates
    updates = self.get_updates(offset=(self.last_update_id + 1),
             ^^^^^^^^^^^^^^^^^^^^^^^^^^^^^^^^^^^^^^^^^^^^^^^^^^
  File "/root/venv/lib/python3.12/site-packages/telebot/__init__.py", line 660, in get_updates
    json_updates = apihelper.get_updates(
                   ^^^^^^^^^^^^^^^^^^^^^^
  File "/root/venv/lib/python3.12/site-packages/telebot/apihelper.py", line 330, in get_updates
    return _make_request(token, method_url, params=payload)
           ^^^^^^^^^^^^^^^^^^^^^^^^^^^^^^^^^^^^^^^^^^^^^^^^
  File "/root/venv/lib/python3.12/site-packages/telebot/apihelper.py", line 168, in _make_request
    json_result = _check_result(method_name, result)
                  ^^^^^^^^^^^^^^^^^^^^^^^^^^^^^^^^^^
  File "/root/venv/lib/python3.12/site-packages/telebot/apihelper.py", line 195, in _check_result
    raise ApiTelegramException(method_name, result, result_json)
telebot.apihelper.ApiTelegramException: A request to the Telegram API was unsuccessful. Error code: 502. Description: Bad Gateway
"
2024-11-05 01:11:23,127 (__init__.py:1241 MainThread) ERROR - TeleBot: "Threaded polling exception: A request to the Telegram API was unsuccessful. Error code: 502. Description: Bad Gateway"
2024-11-05 01:11:23,127 (__init__.py:1243 MainThread) ERROR - TeleBot: "Exception traceback:
Traceback (most recent call last):
  File "/root/venv/lib/python3.12/site-packages/telebot/__init__.py", line 1234, in __threaded_polling
    polling_thread.raise_exceptions()
  File "/root/venv/lib/python3.12/site-packages/telebot/util.py", line 111, in raise_exceptions
    raise self.exception_info
  File "/root/venv/lib/python3.12/site-packages/telebot/util.py", line 93, in run
    task(*args, **kwargs)
  File "/root/venv/lib/python3.12/site-packages/telebot/__init__.py", line 688, in __retrieve_updates
    updates = self.get_updates(offset=(self.last_update_id + 1),
             ^^^^^^^^^^^^^^^^^^^^^^^^^^^^^^^^^^^^^^^^^^^^^^^^^^
  File "/root/venv/lib/python3.12/site-packages/telebot/__init__.py", line 660, in get_updates
    json_updates = apihelper.get_updates(
                   ^^^^^^^^^^^^^^^^^^^^^^
  File "/root/venv/lib/python3.12/site-packages/telebot/apihelper.py", line 330, in get_updates
    return _make_request(token, method_url, params=payload)
           ^^^^^^^^^^^^^^^^^^^^^^^^^^^^^^^^^^^^^^^^^^^^^^^^
  File "/root/venv/lib/python3.12/site-packages/telebot/apihelper.py", line 168, in _make_request
    json_result = _check_result(method_name, result)
                  ^^^^^^^^^^^^^^^^^^^^^^^^^^^^^^^^^^
  File "/root/venv/lib/python3.12/site-packages/telebot/apihelper.py", line 195, in _check_result
    raise ApiTelegramException(method_name, result, result_json)
telebot.apihelper.ApiTelegramException: A request to the Telegram API was unsuccessful. Error code: 502. Description: Bad Gateway
"
2024-11-05 01:11:24,147 (__init__.py:1241 MainThread) ERROR - TeleBot: "Threaded polling exception: A request to the Telegram API was unsuccessful. Error code: 502. Description: Bad Gateway"
2024-11-05 01:11:24,147 (__init__.py:1243 MainThread) ERROR - TeleBot: "Exception traceback:
Traceback (most recent call last):
  File "/root/venv/lib/python3.12/site-packages/telebot/__init__.py", line 1234, in __threaded_polling
    polling_thread.raise_exceptions()
  File "/root/venv/lib/python3.12/site-packages/telebot/util.py", line 111, in raise_exceptions
    raise self.exception_info
  File "/root/venv/lib/python3.12/site-packages/telebot/util.py", line 93, in run
    task(*args, **kwargs)
  File "/root/venv/lib/python3.12/site-packages/telebot/__init__.py", line 688, in __retrieve_updates
    updates = self.get_updates(offset=(self.last_update_id + 1),
             ^^^^^^^^^^^^^^^^^^^^^^^^^^^^^^^^^^^^^^^^^^^^^^^^^^
  File "/root/venv/lib/python3.12/site-packages/telebot/__init__.py", line 660, in get_updates
    json_updates = apihelper.get_updates(
                   ^^^^^^^^^^^^^^^^^^^^^^
  File "/root/venv/lib/python3.12/site-packages/telebot/apihelper.py", line 330, in get_updates
    return _make_request(token, method_url, params=payload)
           ^^^^^^^^^^^^^^^^^^^^^^^^^^^^^^^^^^^^^^^^^^^^^^^^
  File "/root/venv/lib/python3.12/site-packages/telebot/apihelper.py", line 168, in _make_request
    json_result = _check_result(method_name, result)
                  ^^^^^^^^^^^^^^^^^^^^^^^^^^^^^^^^^^
  File "/root/venv/lib/python3.12/site-packages/telebot/apihelper.py", line 195, in _check_result
    raise ApiTelegramException(method_name, result, result_json)
telebot.apihelper.ApiTelegramException: A request to the Telegram API was unsuccessful. Error code: 502. Description: Bad Gateway
"
2024-11-05 01:11:26,171 (__init__.py:1241 MainThread) ERROR - TeleBot: "Threaded polling exception: A request to the Telegram API was unsuccessful. Error code: 502. Description: Bad Gateway"
2024-11-05 01:11:26,172 (__init__.py:1243 MainThread) ERROR - TeleBot: "Exception traceback:
Traceback (most recent call last):
  File "/root/venv/lib/python3.12/site-packages/telebot/__init__.py", line 1234, in __threaded_polling
    polling_thread.raise_exceptions()
  File "/root/venv/lib/python3.12/site-packages/telebot/util.py", line 111, in raise_exceptions
    raise self.exception_info
  File "/root/venv/lib/python3.12/site-packages/telebot/util.py", line 93, in run
    task(*args, **kwargs)
  File "/root/venv/lib/python3.12/site-packages/telebot/__init__.py", line 688, in __retrieve_updates
    updates = self.get_updates(offset=(self.last_update_id + 1),
             ^^^^^^^^^^^^^^^^^^^^^^^^^^^^^^^^^^^^^^^^^^^^^^^^^^
  File "/root/venv/lib/python3.12/site-packages/telebot/__init__.py", line 660, in get_updates
    json_updates = apihelper.get_updates(
                   ^^^^^^^^^^^^^^^^^^^^^^
  File "/root/venv/lib/python3.12/site-packages/telebot/apihelper.py", line 330, in get_updates
    return _make_request(token, method_url, params=payload)
           ^^^^^^^^^^^^^^^^^^^^^^^^^^^^^^^^^^^^^^^^^^^^^^^^
  File "/root/venv/lib/python3.12/site-packages/telebot/apihelper.py", line 168, in _make_request
    json_result = _check_result(method_name, result)
                  ^^^^^^^^^^^^^^^^^^^^^^^^^^^^^^^^^^
  File "/root/venv/lib/python3.12/site-packages/telebot/apihelper.py", line 195, in _check_result
    raise ApiTelegramException(method_name, result, result_json)
telebot.apihelper.ApiTelegramException: A request to the Telegram API was unsuccessful. Error code: 502. Description: Bad Gateway
"
Письмо не отправлено по причине: (451, b'Ratelimit exceeded for mailbox gera.madara@mail.ru. Try again later.')
Письмо не отправлено по причине: (451, b'Ratelimit exceeded for mailbox gera.madara@mail.ru. Try again later.')
Traceback (most recent call last):
  File "/root/venv/lib/python3.12/site-packages/urllib3/connectionpool.py", line 536, in _make_request
    response = conn.getresponse()
               ^^^^^^^^^^^^^^^^^^
  File "/root/venv/lib/python3.12/site-packages/urllib3/connection.py", line 507, in getresponse
    httplib_response = super().getresponse()
                       ^^^^^^^^^^^^^^^^^^^^^
  File "/usr/lib/python3.12/http/client.py", line 1428, in getresponse
    response.begin()
  File "/usr/lib/python3.12/http/client.py", line 331, in begin
    version, status, reason = self._read_status()
                              ^^^^^^^^^^^^^^^^^^^
  File "/usr/lib/python3.12/http/client.py", line 292, in _read_status
    line = str(self.fp.readline(_MAXLINE + 1), "iso-8859-1")
               ^^^^^^^^^^^^^^^^^^^^^^^^^^^^^^
  File "/usr/lib/python3.12/socket.py", line 707, in readinto
    return self._sock.recv_into(b)
           ^^^^^^^^^^^^^^^^^^^^^^^
  File "/usr/lib/python3.12/ssl.py", line 1252, in recv_into
    return self.read(nbytes, buffer)
           ^^^^^^^^^^^^^^^^^^^^^^^^^
  File "/usr/lib/python3.12/ssl.py", line 1104, in read
    return self._sslobj.read(len, buffer)
           ^^^^^^^^^^^^^^^^^^^^^^^^^^^^^^
TimeoutError: The read operation timed out

The above exception was the direct cause of the following exception:

Traceback (most recent call last):
  File "/root/venv/lib/python3.12/site-packages/requests/adapters.py", line 667, in send
  File "/root/venv/lib/python3.12/site-packages/urllib3/connectionpool.py", line 843, in urlopen
    retries = retries.increment(
              ^^^^^^^^^^^^^^^^^^
  File "/root/venv/lib/python3.12/site-packages/urllib3/util/retry.py", line 474, in increment
    raise reraise(type(error), error, _stacktrace)
          ^^^^^^^^^^^^^^^^^^^^^^^^^^^^^^^^^^^^^^^^
  File "/root/venv/lib/python3.12/site-packages/urllib3/util/util.py", line 39, in reraise
    raise value
  File "/root/venv/lib/python3.12/site-packages/urllib3/connectionpool.py", line 789, in urlopen
    response = self._make_request(
               ^^^^^^^^^^^^^^^^^^^
  File "/root/venv/lib/python3.12/site-packages/urllib3/connectionpool.py", line 538, in _make_request
    self._raise_timeout(err=e, url=url, timeout_value=read_timeout)
  File "/root/venv/lib/python3.12/site-packages/urllib3/connectionpool.py", line 369, in _raise_timeout
    raise ReadTimeoutError(
urllib3.exceptions.ReadTimeoutError: HTTPSConnectionPool(host='api.telegram.org', port=443): Read timed out. (read timeout=25)

During handling of the above exception, another exception occurred:

Traceback (most recent call last):
  File "/root/snb/main.py", line 502, in <module>
    bot.polling(none_stop=True)
  File "/root/venv/lib/python3.12/site-packages/telebot/__init__.py", line 1198, in polling
    self.__threaded_polling(non_stop=non_stop, interval=interval, timeout=timeout, long_polling_timeout=long_polling_timeout,
  File "/root/venv/lib/python3.12/site-packages/telebot/__init__.py", line 1273, in __threaded_polling
    raise e
  File "/root/venv/lib/python3.12/site-packages/telebot/__init__.py", line 1234, in __threaded_polling
    polling_thread.raise_exceptions()
  File "/root/venv/lib/python3.12/site-packages/telebot/util.py", line 111, in raise_exceptions
    raise self.exception_info
  File "/root/venv/lib/python3.12/site-packages/telebot/util.py", line 93, in run
    task(*args, **kwargs)
  File "/root/venv/lib/python3.12/site-packages/telebot/__init__.py", line 688, in __retrieve_updates
    updates = self.get_updates(offset=(self.last_update_id + 1), 
              ^^^^^^^^^^^^^^^^^^^^^^^^^^^^^^^^^^^^^^^^^^^^^^^^^^
  File "/root/venv/lib/python3.12/site-packages/telebot/__init__.py", line 660, in get_updates
    json_updates = apihelper.get_updates(
                   ^^^^^^^^^^^^^^^^^^^^^^
  File "/root/venv/lib/python3.12/site-packages/telebot/apihelper.py", line 330, in get_updates
    return _make_request(token, method_url, params=payload)
           ^^^^^^^^^^^^^^^^^^^^^^^^^^^^^^^^^^^^^^^^^^^^^^^^
  File "/root/venv/lib/python3.12/site-packages/telebot/apihelper.py", line 162, in _make_request
    result = _get_req_session().request(
             ^^^^^^^^^^^^^^^^^^^^^^^^^^^
  File "/root/venv/lib/python3.12/site-packages/requests/sessions.py", line 589, in request
    resp = self.send(prep, **send_kwargs)
           ^^^^^^^^^^^^^^^^^^^^^^^^^^^^^^
  File "/root/venv/lib/python3.12/site-packages/requests/sessions.py", line 703, in send
    r = adapter.send(request, **kwargs)
        ^^^^^^^^^^^^^^^^^^^^^^^^^^^^^^^
  File "/root/venv/lib/python3.12/site-packages/requests/adapters.py", line 713, in send
requests.exceptions.ReadTimeout: HTTPSConnectionPool(host='api.telegram.org', port=443): Read timed out. (read timeout=25)
